Workbook

Sheet Sheet 22
A1: Name | B1: Date | C1: Time In | D1: Time Out | E1: Worked Minutes | F1: Late Minutes | G1: Less Than 8 Hours | H1: Status | I1: Target time | J1: Comments
A2: Sheet 21 | B2: 2026-01-01 | C2: 9:03 AM | D2: 5:21 PM | E2: =IF(OR(C2="Absent",D2="Absent",C2="",D2=""),"", (D2-C2)*1440) -> 498 | F2: =IF(OR(C2="",C2="Absent"),"", MAX(0,(C2 - TIME(8,50,0))*1440)) -> 13 | G2: =IF(C2="","", MAX(0,480 - E2)) -> 0 | H2: =IF(OR(TRIM(C2)="Absent", TRIM(C2)="ABSENT"), "Absent", IF(OR(TRIM(C2)="", TRIM(C2)="-", TRIM(D2)="", TRIM(D2)="-"), "Missing", IF( IF(ISNUMBER(C2), C2, IFERROR(TIMEVALUE(C2), 0)) < TIME(8,30,0), "Early", IF( AND( IF(ISNUMBER(C2), C2, IFERROR(TIMEVALUE(C2), 0)) >= TIME(8,30,0), IF(ISNUMBER(C2), C2, IFERROR(TIMEVALUE(C2), 0)) <= TIME(8,50,0), (IF(ISNUMBER(D2), D2, IFERROR(TIMEVALUE(D2), 0)) - IF(ISNUMBER(C2), C2, IFERROR(TIMEVALUE(C2), 0))) >= TIME(8,0,0) ), "On Time", "Late" ) ) ) ) -> Late | I2: 480
A3: Sheet 21 | B3: 2026-01-02 | C3: 9:08 AM | D3: 5:23 PM | E3: =IF(OR(C3="Absent",D3="Absent",C3="",D3=""),"", (D3-C3)*1440) -> 495 | F3: =IF(OR(C3="",C3="Absent"),"", MAX(0,(C3 - TIME(8,50,0))*1440)) -> 18 | G3: =IF(C3="","", MAX(0,480 - E3)) -> 0 | H3: =IF(OR(TRIM(C3)="Absent", TRIM(C3)="ABSENT"), "Absent", IF(OR(TRIM(C3)="", TRIM(C3)="-", TRIM(D3)="", TRIM(D3)="-"), "Missing", IF( IF(ISNUMBER(C3), C3, IFERROR(TIMEVALUE(C3), 0)) < TIME(8,30,0), "Early", IF( AND( IF(ISNUMBER(C3), C3, IFERROR(TIMEVALUE(C3), 0)) >= TIME(8,30,0), IF(ISNUMBER(C3), C3, IFERROR(TIMEVALUE(C3), 0)) <= TIME(8,50,0), (IF(ISNUMBER(D3), D3, IFERROR(TIMEVALUE(D3), 0)) - IF(ISNUMBER(C3), C3, IFERROR(TIMEVALUE(C3), 0))) >= TIME(8,0,0) ), "On Time", "Late" ) ) ) ) -> Late | I3: 480
A4: Sheet 21 | B4: 2026-01-05 | C4: 9:14 AM | D4: 9:14 AM | E4: =IF(OR(C4="Absent",D4="Absent",C4="",D4=""),"", (D4-C4)*1440) -> 0 | F4: =IF(OR(C4="",C4="Absent"),"", MAX(0,(C4 - TIME(8,50,0))*1440)) -> 24 | G4: =IF(C4="","", MAX(0,480 - E4)) -> 480 | H4: =IF(OR(TRIM(C4)="Absent", TRIM(C4)="ABSENT"), "Absent", IF(OR(TRIM(C4)="", TRIM(C4)="-", TRIM(D4)="", TRIM(D4)="-"), "Missing", IF( IF(ISNUMBER(C4), C4, IFERROR(TIMEVALUE(C4), 0)) < TIME(8,30,0), "Early", IF( AND( IF(ISNUMBER(C4), C4, IFERROR(TIMEVALUE(C4), 0)) >= TIME(8,30,0), IF(ISNUMBER(C4), C4, IFERROR(TIMEVALUE(C4), 0)) <= TIME(8,50,0), (IF(ISNUMBER(D4), D4, IFERROR(TIMEVALUE(D4), 0)) - IF(ISNUMBER(C4), C4, IFERROR(TIMEVALUE(C4), 0))) >= TIME(8,0,0) ), "On Time", "Late" ) ) ) ) -> Late | I4: 480
A5: Sheet 21 | B5: 2026-01-06 | C5: 9:13 AM | D5: 5:19 PM | E5: =IF(OR(C5="Absent",D5="Absent",C5="",D5=""),"", (D5-C5)*1440) -> 486 | F5: =IF(OR(C5="",C5="Absent"),"", MAX(0,(C5 - TIME(8,50,0))*1440)) -> 23 | G5: =IF(C5="","", MAX(0,480 - E5)) -> 0 | H5: =IF(OR(TRIM(C5)="Absent", TRIM(C5)="ABSENT"), "Absent", IF(OR(TRIM(C5)="", TRIM(C5)="-", TRIM(D5)="", TRIM(D5)="-"), "Missing", IF( IF(ISNUMBER(C5), C5, IFERROR(TIMEVALUE(C5), 0)) < TIME(8,30,0), "Early", IF( AND( IF(ISNUMBER(C5), C5, IFERROR(TIMEVALUE(C5), 0)) >= TIME(8,30,0), IF(ISNUMBER(C5), C5, IFERROR(TIMEVALUE(C5), 0)) <= TIME(8,50,0), (IF(ISNUMBER(D5), D5, IFERROR(TIMEVALUE(D5), 0)) - IF(ISNUMBER(C5), C5, IFERROR(TIMEVALUE(C5), 0))) >= TIME(8,0,0) ), "On Time", "Late" ) ) ) ) -> Late | I5: 480
A6: Sheet 21 | B6: 2026-01-07 | C6: 9:23 AM | D6: - | E6: =IF(OR(C6="Absent",D6="Absent",C6="",D6=""),"", (D6-C6)*1440) -> #VALUE! | F6: =IF(OR(C6="",C6="Absent"),"", MAX(0,(C6 - TIME(8,50,0))*1440)) -> 33 | G6: =IF(C6="","", MAX(0,480 - E6)) -> #VALUE! | H6: =IF(OR(TRIM(C6)="Absent", TRIM(C6)="ABSENT"), "Absent", IF(OR(TRIM(C6)="", TRIM(C6)="-", TRIM(D6)="", TRIM(D6)="-"), "Missing", IF( IF(ISNUMBER(C6), C6, IFERROR(TIMEVALUE(C6), 0)) < TIME(8,30,0), "Early", IF( AND( IF(ISNUMBER(C6), C6, IFERROR(TIMEVALUE(C6), 0)) >= TIME(8,30,0), IF(ISNUMBER(C6), C6, IFERROR(TIMEVALUE(C6), 0)) <= TIME(8,50,0), (IF(ISNUMBER(D6), D6, IFERROR(TIMEVALUE(D6), 0)) - IF(ISNUMBER(C6), C6, IFERROR(TIMEVALUE(C6), 0))) >= TIME(8,0,0) ), "On Time", "Late" ) ) ) ) -> Missing | I6: 480
A7: Sheet 21 | B7: 2026-01-08 | C7: 9:04 AM | D7: 5:12 PM | E7: =IF(OR(C7="Absent",D7="Absent",C7="",D7=""),"", (D7-C7)*1440) -> 488 | F7: =IF(OR(C7="",C7="Absent"),"", MAX(0,(C7 - TIME(8,50,0))*1440)) -> 14 | G7: =IF(C7="","", MAX(0,480 - E7)) -> 0 | H7: =IF(OR(TRIM(C7)="Absent", TRIM(C7)="ABSENT"), "Absent", IF(OR(TRIM(C7)="", TRIM(C7)="-", TRIM(D7)="", TRIM(D7)="-"), "Missing", IF( IF(ISNUMBER(C7), C7, IFERROR(TIMEVALUE(C7), 0)) < TIME(8,30,0), "Early", IF( AND( IF(ISNUMBER(C7), C7, IFERROR(TIMEVALUE(C7), 0)) >= TIME(8,30,0), IF(ISNUMBER(C7), C7, IFERROR(TIMEVALUE(C7), 0)) <= TIME(8,50,0), (IF(ISNUMBER(D7), D7, IFERROR(TIMEVALUE(D7), 0)) - IF(ISNUMBER(C7), C7, IFERROR(TIMEVALUE(C7), 0))) >= TIME(8,0,0) ), "On Time", "Late" ) ) ) ) -> Late | I7: 480
A8: Sheet 21 | B8: 2026-01-09 | C8: 9:18 AM | D8: 5:34 PM | E8: =IF(OR(C8="Absent",D8="Absent",C8="",D8=""),"", (D8-C8)*1440) -> 496 | F8: =IF(OR(C8="",C8="Absent"),"", MAX(0,(C8 - TIME(8,50,0))*1440)) -> 28 | G8: =IF(C8="","", MAX(0,480 - E8)) -> 0 | H8: =IF(OR(TRIM(C8)="Absent", TRIM(C8)="ABSENT"), "Absent", IF(OR(TRIM(C8)="", TRIM(C8)="-", TRIM(D8)="", TRIM(D8)="-"), "Missing", IF( IF(ISNUMBER(C8), C8, IFERROR(TIMEVALUE(C8), 0)) < TIME(8,30,0), "Early", IF( AND( IF(ISNUMBER(C8), C8, IFERROR(TIMEVALUE(C8), 0)) >= TIME(8,30,0), IF(ISNUMBER(C8), C8, IFERROR(TIMEVALUE(C8), 0)) <= TIME(8,50,0), (IF(ISNUMBER(D8), D8, IFERROR(TIMEVALUE(D8), 0)) - IF(ISNUMBER(C8), C8, IFERROR(TIMEVALUE(C8), 0))) >= TIME(8,0,0) ), "On Time", "Late" ) ) ) ) -> Late | I8: 480
A9: Sheet 21 | B9: 2026-01-12 | C9: 9:11 AM | D9: 5:21 PM | E9: =IF(OR(C9="Absent",D9="Absent",C9="",D9=""),"", (D9-C9)*1440) -> 490 | F9: =IF(OR(C9="",C9="Absent"),"", MAX(0,(C9 - TIME(8,50,0))*1440)) -> 21 | G9: =IF(C9="","", MAX(0,480 - E9)) -> 0 | H9: =IF(OR(TRIM(C9)="Absent", TRIM(C9)="ABSENT"), "Absent", IF(OR(TRIM(C9)="", TRIM(C9)="-", TRIM(D9)="", TRIM(D9)="-"), "Missing", IF( IF(ISNUMBER(C9), C9, IFERROR(TIMEVALUE(C9), 0)) < TIME(8,30,0), "Early", IF( AND( IF(ISNUMBER(C9), C9, IFERROR(TIMEVALUE(C9), 0)) >= TIME(8,30,0), IF(ISNUMBER(C9), C9, IFERROR(TIMEVALUE(C9), 0)) <= TIME(8,50,0), (IF(ISNUMBER(D9), D9, IFERROR(TIMEVALUE(D9), 0)) - IF(ISNUMBER(C9), C9, IFERROR(TIMEVALUE(C9), 0))) >= TIME(8,0,0) ), "On Time", "Late" ) ) ) ) -> Late | I9: 480
A10: Sheet 21 | B10: 2026-01-13 | C10: 9:05 AM | D10: 5:21 PM | E10: =IF(OR(C10="Absent",D10="Absent",C10="",D10=""),"", (D10-C10)*1440) -> 496 | F10: =IF(OR(C10="",C10="Absent"),"", MAX(0,(C10 - TIME(8,50,0))*1440)) -> 15 | G10: =IF(C10="","", MAX(0,480 - E10)) -> 0 | H10: =IF(OR(TRIM(C10)="Absent", TRIM(C10)="ABSENT"), "Absent", IF(OR(TRIM(C10)="", TRIM(C10)="-", TRIM(D10)="", TRIM(D10)="-"), "Missing", IF( IF(ISNUMBER(C10), C10, IFERROR(TIMEVALUE(C10), 0)) < TIME(8,30,0), "Early", IF( AND( IF(ISNUMBER(C10), C10, IFERROR(TIMEVALUE(C10), 0)) >= TIME(8,30,0), IF(ISNUMBER(C10), C10, IFERROR(TIMEVALUE(C10), 0)) <= TIME(8,50,0), (IF(ISNUMBER(D10), D10, IFERROR(TIMEVALUE(D10), 0)) - IF(ISNUMBER(C10), C10, IFERROR(TIMEVALUE(C10), 0))) >= TIME(8,0,0) ), "On Time", "Late" ) ) ) ) -> Late | I10: 480
A11: Sheet 21 | B11: 2026-01-14 | C11: 9:05 AM | D11: 5:29 PM | E11: =IF(OR(C11="Absent",D11="Absent",C11="",D11=""),"", (D11-C11)*1440) -> 504 | F11: =IF(OR(C11="",C11="Absent"),"", MAX(0,(C11 - TIME(8,50,0))*1440)) -> 15 | G11: =IF(C11="","", MAX(0,480 - E11)) -> 0 | H11: =IF(OR(TRIM(C11)="Absent", TRIM(C11)="ABSENT"), "Absent", IF(OR(TRIM(C11)="", TRIM(C11)="-", TRIM(D11)="", TRIM(D11)="-"), "Missing", IF( IF(ISNUMBER(C11), C11, IFERROR(TIMEVALUE(C11), 0)) < TIME(8,30,0), "Early", IF( AND( IF(ISNUMBER(C11), C11, IFERROR(TIMEVALUE(C11), 0)) >= TIME(8,30,0), IF(ISNUMBER(C11), C11, IFERROR(TIMEVALUE(C11), 0)) <= TIME(8,50,0), (IF(ISNUMBER(D11), D11, IFERROR(TIMEVALUE(D11), 0)) - IF(ISNUMBER(C11), C11, IFERROR(TIMEVALUE(C11), 0))) >= TIME(8,0,0) ), "On Time", "Late" ) ) ) ) -> Late | I11: 480
A12: Sheet 21 | B12: 2026-01-15 | C12: 9:15 AM | D12: 5:40 PM | E12: =IF(OR(C12="Absent",D12="Absent",C12="",D12=""),"", (D12-C12)*1440) -> 505 | F12: =IF(OR(C12="",C12="Absent"),"", MAX(0,(C12 - TIME(8,50,0))*1440)) -> 25 | G12: =IF(C12="","", MAX(0,480 - E12)) -> 0 | H12: =IF(OR(TRIM(C12)="Absent", TRIM(C12)="ABSENT"), "Absent", IF(OR(TRIM(C12)="", TRIM(C12)="-", TRIM(D12)="", TRIM(D12)="-"), "Missing", IF( IF(ISNUMBER(C12), C12, IFERROR(TIMEVALUE(C12), 0)) < TIME(8,30,0), "Early", IF( AND( IF(ISNUMBER(C12), C12, IFERROR(TIMEVALUE(C12), 0)) >= TIME(8,30,0), IF(ISNUMBER(C12), C12, IFERROR(TIMEVALUE(C12), 0)) <= TIME(8,50,0), (IF(ISNUMBER(D12), D12, IFERROR(TIMEVALUE(D12), 0)) - IF(ISNUMBER(C12), C12, IFERROR(TIMEVALUE(C12), 0))) >= TIME(8,0,0) ), "On Time", "Late" ) ) ) ) -> Late | I12: 480
A13: Sheet 21 | B13: 2026-01-16 | C13: 9:03 AM | D13: 5:47 PM | E13: =IF(OR(C13="Absent",D13="Absent",C13="",D13=""),"", (D13-C13)*1440) -> 524 | F13: =IF(OR(C13="",C13="Absent"),"", MAX(0,(C13 - TIME(8,50,0))*1440)) -> 13 | G13: =IF(C13="","", MAX(0,480 - E13)) -> 0 | H13: =IF(OR(TRIM(C13)="Absent", TRIM(C13)="ABSENT"), "Absent", IF(OR(TRIM(C13)="", TRIM(C13)="-", TRIM(D13)="", TRIM(D13)="-"), "Missing", IF( IF(ISNUMBER(C13), C13, IFERROR(TIMEVALUE(C13), 0)) < TIME(8,30,0), "Early", IF( AND( IF(ISNUMBER(C13), C13, IFERROR(TIMEVALUE(C13), 0)) >= TIME(8,30,0), IF(ISNUMBER(C13), C13, IFERROR(TIMEVALUE(C13), 0)) <= TIME(8,50,0), (IF(ISNUMBER(D13), D13, IFERROR(TIMEVALUE(D13), 0)) - IF(ISNUMBER(C13), C13, IFERROR(TIMEVALUE(C13), 0))) >= TIME(8,0,0) ), "On Time", "Late" ) ) ) ) -> Late | I13: 480
... A23: Sheet 21 | B23: 2026-01-30 | C23: 9:27 AM | D23: 5:33 PM | E23: =IF(OR(C23="Absent",D23="Absent",C23="",D23=""),"", (D23-C23)*1440) -> 486 | F23: =IF(OR(C23="",C23="Absent"),"", MAX(0,(C23 - TIME(8,50,0))*1440)) -> 37 | G23: =IF(C23="","", MAX(0,480 - E23)) -> 0 | H23: =IF(OR(TRIM(C23)="Absent", TRIM(C23)="ABSENT"), "Absent", IF(OR(TRIM(C23)="", TRIM(C23)="-", TRIM(D23)="", TRIM(D23)="-"), "Missing", IF( IF(ISNUMBER(C23), C23, IFERROR(TIMEVALUE(C23), 0)) < TIME(8,30,0), "Early", IF( AND( IF(ISNUMBER(C23), C23, IFERROR(TIMEVALUE(C23), 0)) >= TIME(8,30,0), IF(ISNUMBER(C23), C23, IFERROR(TIMEVALUE(C23), 0)) <= TIME(8,50,0), (IF(ISNUMBER(D23), D23, IFERROR(TIMEVALUE(D23), 0)) - IF(ISNUMBER(C23), C23, IFERROR(TIMEVALUE(C23), 0))) >= TIME(8,0,0) ), "On Time", "Late" ) ) ) ) -> Late | I23: 480

Sheet Sheet 21
A1: Name | B1: Date | C1: Time In | D1: Time Out | E1: Worked Minutes | F1: Late Minutes | G1: Less Than 8 Hours | H1: Status | I1: Target time | J1: Comments
A2: Sheet 21 | B2: 2026-01-01 | C2: 9:03 AM | D2: 5:21 PM | E2: =IF(OR(C2="Absent",D2="Absent",C2="",D2=""),"", (D2-C2)*1440) -> 498 | F2: =IF(OR(C2="",C2="Absent"),"", MAX(0,(C2 - TIME(8,50,0))*1440)) -> 13 | G2: =IF(C2="","", MAX(0,480 - E2)) -> 0 | H2: =IF(OR(TRIM(C2)="Absent", TRIM(C2)="ABSENT"), "Absent", IF(OR(TRIM(C2)="", TRIM(C2)="-", TRIM(D2)="", TRIM(D2)="-"), "Missing", IF( IF(ISNUMBER(C2), C2, IFERROR(TIMEVALUE(C2), 0)) < TIME(8,30,0), "Early", IF( AND( IF(ISNUMBER(C2), C2, IFERROR(TIMEVALUE(C2), 0)) >= TIME(8,30,0), IF(ISNUMBER(C2), C2, IFERROR(TIMEVALUE(C2), 0)) <= TIME(8,50,0), (IF(ISNUMBER(D2), D2, IFERROR(TIMEVALUE(D2), 0)) - IF(ISNUMBER(C2), C2, IFERROR(TIMEVALUE(C2), 0))) >= TIME(8,0,0) ), "On Time", "Late" ) ) ) ) -> Late | I2: 480
A3: Sheet 21 | B3: 2026-01-02 | C3: 9:08 AM | D3: 5:23 PM | E3: =IF(OR(C3="Absent",D3="Absent",C3="",D3=""),"", (D3-C3)*1440) -> 495 | F3: =IF(OR(C3="",C3="Absent"),"", MAX(0,(C3 - TIME(8,50,0))*1440)) -> 18 | G3: =IF(C3="","", MAX(0,480 - E3)) -> 0 | H3: =IF(OR(TRIM(C3)="Absent", TRIM(C3)="ABSENT"), "Absent", IF(OR(TRIM(C3)="", TRIM(C3)="-", TRIM(D3)="", TRIM(D3)="-"), "Missing", IF( IF(ISNUMBER(C3), C3, IFERROR(TIMEVALUE(C3), 0)) < TIME(8,30,0), "Early", IF( AND( IF(ISNUMBER(C3), C3, IFERROR(TIMEVALUE(C3), 0)) >= TIME(8,30,0), IF(ISNUMBER(C3), C3, IFERROR(TIMEVALUE(C3), 0)) <= TIME(8,50,0), (IF(ISNUMBER(D3), D3, IFERROR(TIMEVALUE(D3), 0)) - IF(ISNUMBER(C3), C3, IFERROR(TIMEVALUE(C3), 0))) >= TIME(8,0,0) ), "On Time", "Late" ) ) ) ) -> Late | I3: 480
A4: Sheet 21 | B4: 2026-01-05 | C4: 9:14 AM | D4: 9:14 AM | E4: =IF(OR(C4="Absent",D4="Absent",C4="",D4=""),"", (D4-C4)*1440) -> 0 | F4: =IF(OR(C4="",C4="Absent"),"", MAX(0,(C4 - TIME(8,50,0))*1440)) -> 24 | G4: =IF(C4="","", MAX(0,480 - E4)) -> 480 | H4: =IF(OR(TRIM(C4)="Absent", TRIM(C4)="ABSENT"), "Absent", IF(OR(TRIM(C4)="", TRIM(C4)="-", TRIM(D4)="", TRIM(D4)="-"), "Missing", IF( IF(ISNUMBER(C4), C4, IFERROR(TIMEVALUE(C4), 0)) < TIME(8,30,0), "Early", IF( AND( IF(ISNUMBER(C4), C4, IFERROR(TIMEVALUE(C4), 0)) >= TIME(8,30,0), IF(ISNUMBER(C4), C4, IFERROR(TIMEVALUE(C4), 0)) <= TIME(8,50,0), (IF(ISNUMBER(D4), D4, IFERROR(TIMEVALUE(D4), 0)) - IF(ISNUMBER(C4), C4, IFERROR(TIMEVALUE(C4), 0))) >= TIME(8,0,0) ), "On Time", "Late" ) ) ) ) -> Late | I4: 480
A5: Sheet 21 | B5: 2026-01-06 | C5: 9:13 AM | D5: 5:19 PM | E5: =IF(OR(C5="Absent",D5="Absent",C5="",D5=""),"", (D5-C5)*1440) -> 486 | F5: =IF(OR(C5="",C5="Absent"),"", MAX(0,(C5 - TIME(8,50,0))*1440)) -> 23 | G5: =IF(C5="","", MAX(0,480 - E5)) -> 0 | H5: =IF(OR(TRIM(C5)="Absent", TRIM(C5)="ABSENT"), "Absent", IF(OR(TRIM(C5)="", TRIM(C5)="-", TRIM(D5)="", TRIM(D5)="-"), "Missing", IF( IF(ISNUMBER(C5), C5, IFERROR(TIMEVALUE(C5), 0)) < TIME(8,30,0), "Early", IF( AND( IF(ISNUMBER(C5), C5, IFERROR(TIMEVALUE(C5), 0)) >= TIME(8,30,0), IF(ISNUMBER(C5), C5, IFERROR(TIMEVALUE(C5), 0)) <= TIME(8,50,0), (IF(ISNUMBER(D5), D5, IFERROR(TIMEVALUE(D5), 0)) - IF(ISNUMBER(C5), C5, IFERROR(TIMEVALUE(C5), 0))) >= TIME(8,0,0) ), "On Time", "Late" ) ) ) ) -> Late | I5: 480
A6: Sheet 21 | B6: 2026-01-07 | C6: 9:23 AM | D6: - | E6: =IF(OR(C6="Absent",D6="Absent",C6="",D6=""),"", (D6-C6)*1440) -> #VALUE! | F6: =IF(OR(C6="",C6="Absent"),"", MAX(0,(C6 - TIME(8,50,0))*1440)) -> 33 | G6: =IF(C6="","", MAX(0,480 - E6)) -> #VALUE! | H6: =IF(OR(TRIM(C6)="Absent", TRIM(C6)="ABSENT"), "Absent", IF(OR(TRIM(C6)="", TRIM(C6)="-", TRIM(D6)="", TRIM(D6)="-"), "Missing", IF( IF(ISNUMBER(C6), C6, IFERROR(TIMEVALUE(C6), 0)) < TIME(8,30,0), "Early", IF( AND( IF(ISNUMBER(C6), C6, IFERROR(TIMEVALUE(C6), 0)) >= TIME(8,30,0), IF(ISNUMBER(C6), C6, IFERROR(TIMEVALUE(C6), 0)) <= TIME(8,50,0), (IF(ISNUMBER(D6), D6, IFERROR(TIMEVALUE(D6), 0)) - IF(ISNUMBER(C6), C6, IFERROR(TIMEVALUE(C6), 0))) >= TIME(8,0,0) ), "On Time", "Late" ) ) ) ) -> Missing | I6: 480
A7: Sheet 21 | B7: 2026-01-08 | C7: 9:04 AM | D7: 5:12 PM | E7: =IF(OR(C7="Absent",D7="Absent",C7="",D7=""),"", (D7-C7)*1440) -> 488 | F7: =IF(OR(C7="",C7="Absent"),"", MAX(0,(C7 - TIME(8,50,0))*1440)) -> 14 | G7: =IF(C7="","", MAX(0,480 - E7)) -> 0 | H7: =IF(OR(TRIM(C7)="Absent", TRIM(C7)="ABSENT"), "Absent", IF(OR(TRIM(C7)="", TRIM(C7)="-", TRIM(D7)="", TRIM(D7)="-"), "Missing", IF( IF(ISNUMBER(C7), C7, IFERROR(TIMEVALUE(C7), 0)) < TIME(8,30,0), "Early", IF( AND( IF(ISNUMBER(C7), C7, IFERROR(TIMEVALUE(C7), 0)) >= TIME(8,30,0), IF(ISNUMBER(C7), C7, IFERROR(TIMEVALUE(C7), 0)) <= TIME(8,50,0), (IF(ISNUMBER(D7), D7, IFERROR(TIMEVALUE(D7), 0)) - IF(ISNUMBER(C7), C7, IFERROR(TIMEVALUE(C7), 0))) >= TIME(8,0,0) ), "On Time", "Late" ) ) ) ) -> Late | I7: 480
A8: Sheet 21 | B8: 2026-01-09 | C8: 9:18 AM | D8: 5:34 PM | E8: =IF(OR(C8="Absent",D8="Absent",C8="",D8=""),"", (D8-C8)*1440) -> 496 | F8: =IF(OR(C8="",C8="Absent"),"", MAX(0,(C8 - TIME(8,50,0))*1440)) -> 28 | G8: =IF(C8="","", MAX(0,480 - E8)) -> 0 | H8: =IF(OR(TRIM(C8)="Absent", TRIM(C8)="ABSENT"), "Absent", IF(OR(TRIM(C8)="", TRIM(C8)="-", TRIM(D8)="", TRIM(D8)="-"), "Missing", IF( IF(ISNUMBER(C8), C8, IFERROR(TIMEVALUE(C8), 0)) < TIME(8,30,0), "Early", IF( AND( IF(ISNUMBER(C8), C8, IFERROR(TIMEVALUE(C8), 0)) >= TIME(8,30,0), IF(ISNUMBER(C8), C8, IFERROR(TIMEVALUE(C8), 0)) <= TIME(8,50,0), (IF(ISNUMBER(D8), D8, IFERROR(TIMEVALUE(D8), 0)) - IF(ISNUMBER(C8), C8, IFERROR(TIMEVALUE(C8), 0))) >= TIME(8,0,0) ), "On Time", "Late" ) ) ) ) -> Late | I8: 480
A9: Sheet 21 | B9: 2026-01-12 | C9: 9:11 AM | D9: 5:21 PM | E9: =IF(OR(C9="Absent",D9="Absent",C9="",D9=""),"", (D9-C9)*1440) -> 490 | F9: =IF(OR(C9="",C9="Absent"),"", MAX(0,(C9 - TIME(8,50,0))*1440)) -> 21 | G9: =IF(C9="","", MAX(0,480 - E9)) -> 0 | H9: =IF(OR(TRIM(C9)="Absent", TRIM(C9)="ABSENT"), "Absent", IF(OR(TRIM(C9)="", TRIM(C9)="-", TRIM(D9)="", TRIM(D9)="-"), "Missing", IF( IF(ISNUMBER(C9), C9, IFERROR(TIMEVALUE(C9), 0)) < TIME(8,30,0), "Early", IF( AND( IF(ISNUMBER(C9), C9, IFERROR(TIMEVALUE(C9), 0)) >= TIME(8,30,0), IF(ISNUMBER(C9), C9, IFERROR(TIMEVALUE(C9), 0)) <= TIME(8,50,0), (IF(ISNUMBER(D9), D9, IFERROR(TIMEVALUE(D9), 0)) - IF(ISNUMBER(C9), C9, IFERROR(TIMEVALUE(C9), 0))) >= TIME(8,0,0) ), "On Time", "Late" ) ) ) ) -> Late | I9: 480
A10: Sheet 21 | B10: 2026-01-13 | C10: 9:05 AM | D10: 5:21 PM | E10: =IF(OR(C10="Absent",D10="Absent",C10="",D10=""),"", (D10-C10)*1440) -> 496 | F10: =IF(OR(C10="",C10="Absent"),"", MAX(0,(C10 - TIME(8,50,0))*1440)) -> 15 | G10: =IF(C10="","", MAX(0,480 - E10)) -> 0 | H10: =IF(OR(TRIM(C10)="Absent", TRIM(C10)="ABSENT"), "Absent", IF(OR(TRIM(C10)="", TRIM(C10)="-", TRIM(D10)="", TRIM(D10)="-"), "Missing", IF( IF(ISNUMBER(C10), C10, IFERROR(TIMEVALUE(C10), 0)) < TIME(8,30,0), "Early", IF( AND( IF(ISNUMBER(C10), C10, IFERROR(TIMEVALUE(C10), 0)) >= TIME(8,30,0), IF(ISNUMBER(C10), C10, IFERROR(TIMEVALUE(C10), 0)) <= TIME(8,50,0), (IF(ISNUMBER(D10), D10, IFERROR(TIMEVALUE(D10), 0)) - IF(ISNUMBER(C10), C10, IFERROR(TIMEVALUE(C10), 0))) >= TIME(8,0,0) ), "On Time", "Late" ) ) ) ) -> Late | I10: 480
A11: Sheet 21 | B11: 2026-01-14 | C11: 9:05 AM | D11: 5:29 PM | E11: =IF(OR(C11="Absent",D11="Absent",C11="",D11=""),"", (D11-C11)*1440) -> 504 | F11: =IF(OR(C11="",C11="Absent"),"", MAX(0,(C11 - TIME(8,50,0))*1440)) -> 15 | G11: =IF(C11="","", MAX(0,480 - E11)) -> 0 | H11: =IF(OR(TRIM(C11)="Absent", TRIM(C11)="ABSENT"), "Absent", IF(OR(TRIM(C11)="", TRIM(C11)="-", TRIM(D11)="", TRIM(D11)="-"), "Missing", IF( IF(ISNUMBER(C11), C11, IFERROR(TIMEVALUE(C11), 0)) < TIME(8,30,0), "Early", IF( AND( IF(ISNUMBER(C11), C11, IFERROR(TIMEVALUE(C11), 0)) >= TIME(8,30,0), IF(ISNUMBER(C11), C11, IFERROR(TIMEVALUE(C11), 0)) <= TIME(8,50,0), (IF(ISNUMBER(D11), D11, IFERROR(TIMEVALUE(D11), 0)) - IF(ISNUMBER(C11), C11, IFERROR(TIMEVALUE(C11), 0))) >= TIME(8,0,0) ), "On Time", "Late" ) ) ) ) -> Late | I11: 480
A12: Sheet 21 | B12: 2026-01-15 | C12: 9:15 AM | D12: 5:40 PM | E12: =IF(OR(C12="Absent",D12="Absent",C12="",D12=""),"", (D12-C12)*1440) -> 505 | F12: =IF(OR(C12="",C12="Absent"),"", MAX(0,(C12 - TIME(8,50,0))*1440)) -> 25 | G12: =IF(C12="","", MAX(0,480 - E12)) -> 0 | H12: =IF(OR(TRIM(C12)="Absent", TRIM(C12)="ABSENT"), "Absent", IF(OR(TRIM(C12)="", TRIM(C12)="-", TRIM(D12)="", TRIM(D12)="-"), "Missing", IF( IF(ISNUMBER(C12), C12, IFERROR(TIMEVALUE(C12), 0)) < TIME(8,30,0), "Early", IF( AND( IF(ISNUMBER(C12), C12, IFERROR(TIMEVALUE(C12), 0)) >= TIME(8,30,0), IF(ISNUMBER(C12), C12, IFERROR(TIMEVALUE(C12), 0)) <= TIME(8,50,0), (IF(ISNUMBER(D12), D12, IFERROR(TIMEVALUE(D12), 0)) - IF(ISNUMBER(C12), C12, IFERROR(TIMEVALUE(C12), 0))) >= TIME(8,0,0) ), "On Time", "Late" ) ) ) ) -> Late | I12: 480
A13: Sheet 21 | B13: 2026-01-16 | C13: 9:03 AM | D13: 5:47 PM | E13: =IF(OR(C13="Absent",D13="Absent",C13="",D13=""),"", (D13-C13)*1440) -> 524 | F13: =IF(OR(C13="",C13="Absent"),"", MAX(0,(C13 - TIME(8,50,0))*1440)) -> 13 | G13: =IF(C13="","", MAX(0,480 - E13)) -> 0 | H13: =IF(OR(TRIM(C13)="Absent", TRIM(C13)="ABSENT"), "Absent", IF(OR(TRIM(C13)="", TRIM(C13)="-", TRIM(D13)="", TRIM(D13)="-"), "Missing", IF( IF(ISNUMBER(C13), C13, IFERROR(TIMEVALUE(C13), 0)) < TIME(8,30,0), "Early", IF( AND( IF(ISNUMBER(C13), C13, IFERROR(TIMEVALUE(C13), 0)) >= TIME(8,30,0), IF(ISNUMBER(C13), C13, IFERROR(TIMEVALUE(C13), 0)) <= TIME(8,50,0), (IF(ISNUMBER(D13), D13, IFERROR(TIMEVALUE(D13), 0)) - IF(ISNUMBER(C13), C13, IFERROR(TIMEVALUE(C13), 0))) >= TIME(8,0,0) ), "On Time", "Late" ) ) ) ) -> Late | I13: 480
... A23: Sheet 21 | B23: 2026-01-30 | C23: 9:27 AM | D23: 5:33 PM | E23: =IF(OR(C23="Absent",D23="Absent",C23="",D23=""),"", (D23-C23)*1440) -> 486 | F23: =IF(OR(C23="",C23="Absent"),"", MAX(0,(C23 - TIME(8,50,0))*1440)) -> 37 | G23: =IF(C23="","", MAX(0,480 - E23)) -> 0 | H23: =IF(OR(TRIM(C23)="Absent", TRIM(C23)="ABSENT"), "Absent", IF(OR(TRIM(C23)="", TRIM(C23)="-", TRIM(D23)="", TRIM(D23)="-"), "Missing", IF( IF(ISNUMBER(C23), C23, IFERROR(TIMEVALUE(C23), 0)) < TIME(8,30,0), "Early", IF( AND( IF(ISNUMBER(C23), C23, IFERROR(TIMEVALUE(C23), 0)) >= TIME(8,30,0), IF(ISNUMBER(C23), C23, IFERROR(TIMEVALUE(C23), 0)) <= TIME(8,50,0), (IF(ISNUMBER(D23), D23, IFERROR(TIMEVALUE(D23), 0)) - IF(ISNUMBER(C23), C23, IFERROR(TIMEVALUE(C23), 0))) >= TIME(8,0,0) ), "On Time", "Late" ) ) ) ) -> Late | I23: 480

Sheet Sheet 20
A1: Name | B1: Date | C1: Time In | D1: Time Out | E1: Worked Minutes | F1: Late Minutes | G1: Less Than 8 Hours | H1: Status | I1: Target time | J1: Comments
A2: Sheet 20 | B2: 2026-01-01 | C2: 9:01 AM | D2: 4:35 PM | E2: =IF(OR(C2="Absent",D2="Absent",C2="",D2=""),"", (D2-C2)*1440) -> 454 | F2: =IF(OR(C2="",C2="Absent"),"", MAX(0,(C2 - TIME(8,50,0))*1440)) -> 11 | G2: =IF(C2="","", MAX(0,480 - E2)) -> 26 | H2: =IF(OR(TRIM(C2)="Absent", TRIM(C2)="ABSENT"), "Absent", IF(OR(TRIM(C2)="", TRIM(C2)="-", TRIM(D2)="", TRIM(D2)="-"), "Missing", IF( IF(ISNUMBER(C2), C2, IFERROR(TIMEVALUE(C2), 0)) < TIME(8,30,0), "Early", IF( AND( IF(ISNUMBER(C2), C2, IFERROR(TIMEVALUE(C2), 0)) >= TIME(8,30,0), IF(ISNUMBER(C2), C2, IFERROR(TIMEVALUE(C2), 0)) <= TIME(8,50,0), (IF(ISNUMBER(D2), D2, IFERROR(TIMEVALUE(D2), 0)) - IF(ISNUMBER(C2), C2, IFERROR(TIMEVALUE(C2), 0))) >= TIME(8,0,0) ), "On Time", "Late" ) ) ) ) -> Late | I2: 480
A3: Sheet 20 | B3: 2026-01-02 | C3: 8:49 AM | D3: 4:57 PM | E3: =IF(OR(C3="Absent",D3="Absent",C3="",D3=""),"", (D3-C3)*1440) -> 488 | F3: =IF(OR(C3="",C3="Absent"),"", MAX(0,(C3 - TIME(8,50,0))*1440)) -> 0 | G3: =IF(C3="","", MAX(0,480 - E3)) -> 0 | H3: =IF(OR(TRIM(C3)="Absent", TRIM(C3)="ABSENT"), "Absent", IF(OR(TRIM(C3)="", TRIM(C3)="-", TRIM(D3)="", TRIM(D3)="-"), "Missing", IF( IF(ISNUMBER(C3), C3, IFERROR(TIMEVALUE(C3), 0)) < TIME(8,30,0), "Early", IF( AND( IF(ISNUMBER(C3), C3, IFERROR(TIMEVALUE(C3), 0)) >= TIME(8,30,0), IF(ISNUMBER(C3), C3, IFERROR(TIMEVALUE(C3), 0)) <= TIME(8,50,0), (IF(ISNUMBER(D3), D3, IFERROR(TIMEVALUE(D3), 0)) - IF(ISNUMBER(C3), C3, IFERROR(TIMEVALUE(C3), 0))) >= TIME(8,0,0) ), "On Time", "Late" ) ) ) ) -> On Time | I3: 480
A4: Sheet 20 | B4: 2026-01-05 | C4: 8:46 AM | D4: 8:46 AM | E4: =IF(OR(C4="Absent",D4="Absent",C4="",D4=""),"", (D4-C4)*1440) -> 0 | F4: =IF(OR(C4="",C4="Absent"),"", MAX(0,(C4 - TIME(8,50,0))*1440)) -> 0 | G4: =IF(C4="","", MAX(0,480 - E4)) -> 480 | H4: =IF(OR(TRIM(C4)="Absent", TRIM(C4)="ABSENT"), "Absent", IF(OR(TRIM(C4)="", TRIM(C4)="-", TRIM(D4)="", TRIM(D4)="-"), "Missing", IF( IF(ISNUMBER(C4), C4, IFERROR(TIMEVALUE(C4), 0)) < TIME(8,30,0), "Early", IF( AND( IF(ISNUMBER(C4), C4, IFERROR(TIMEVALUE(C4), 0)) >= TIME(8,30,0), IF(ISNUMBER(C4), C4, IFERROR(TIMEVALUE(C4), 0)) <= TIME(8,50,0), (IF(ISNUMBER(D4), D4, IFERROR(TIMEVALUE(D4), 0)) - IF(ISNUMBER(C4), C4, IFERROR(TIMEVALUE(C4), 0))) >= TIME(8,0,0) ), "On Time", "Late" ) ) ) ) -> Late | I4: 480
A5: Sheet 20 | B5: 2026-01-06 | C5: 8:45 AM | D5: 4:59 PM | E5: =IF(OR(C5="Absent",D5="Absent",C5="",D5=""),"", (D5-C5)*1440) -> 494 | F5: =IF(OR(C5="",C5="Absent"),"", MAX(0,(C5 - TIME(8,50,0))*1440)) -> 0 | G5: =IF(C5="","", MAX(0,480 - E5)) -> 0 | H5: =IF(OR(TRIM(C5)="Absent", TRIM(C5)="ABSENT"), "Absent", IF(OR(TRIM(C5)="", TRIM(C5)="-", TRIM(D5)="", TRIM(D5)="-"), "Missing", IF( IF(ISNUMBER(C5), C5, IFERROR(TIMEVALUE(C5), 0)) < TIME(8,30,0), "Early", IF( AND( IF(ISNUMBER(C5), C5, IFERROR(TIMEVALUE(C5), 0)) >= TIME(8,30,0), IF(ISNUMBER(C5), C5, IFERROR(TIMEVALUE(C5), 0)) <= TIME(8,50,0), (IF(ISNUMBER(D5), D5, IFERROR(TIMEVALUE(D5), 0)) - IF(ISNUMBER(C5), C5, IFERROR(TIMEVALUE(C5), 0))) >= TIME(8,0,0) ), "On Time", "Late" ) ) ) ) -> On Time | I5: 480
A6: Sheet 20 | B6: 2026-01-07 | C6: 8:46 AM | D6: 4:45 PM | E6: =IF(OR(C6="Absent",D6="Absent",C6="",D6=""),"", (D6-C6)*1440) -> 479 | F6: =IF(OR(C6="",C6="Absent"),"", MAX(0,(C6 - TIME(8,50,0))*1440)) -> 0 | G6: =IF(C6="","", MAX(0,480 - E6)) -> 1 | H6: =IF(OR(TRIM(C6)="Absent", TRIM(C6)="ABSENT"), "Absent", IF(OR(TRIM(C6)="", TRIM(C6)="-", TRIM(D6)="", TRIM(D6)="-"), "Missing", IF( IF(ISNUMBER(C6), C6, IFERROR(TIMEVALUE(C6), 0)) < TIME(8,30,0), "Early", IF( AND( IF(ISNUMBER(C6), C6, IFERROR(TIMEVALUE(C6), 0)) >= TIME(8,30,0), IF(ISNUMBER(C6), C6, IFERROR(TIMEVALUE(C6), 0)) <= TIME(8,50,0), (IF(ISNUMBER(D6), D6, IFERROR(TIMEVALUE(D6), 0)) - IF(ISNUMBER(C6), C6, IFERROR(TIMEVALUE(C6), 0))) >= TIME(8,0,0) ), "On Time", "Late" ) ) ) ) -> Late | I6: 480
A7: Sheet 20 | B7: 2026-01-08 | C7: 8:46 AM | D7: 4:47 PM | E7: =IF(OR(C7="Absent",D7="Absent",C7="",D7=""),"", (D7-C7)*1440) -> 481 | F7: =IF(OR(C7="",C7="Absent"),"", MAX(0,(C7 - TIME(8,50,0))*1440)) -> 0 | G7: =IF(C7="","", MAX(0,480 - E7)) -> 0 | H7: =IF(OR(TRIM(C7)="Absent", TRIM(C7)="ABSENT"), "Absent", IF(OR(TRIM(C7)="", TRIM(C7)="-", TRIM(D7)="", TRIM(D7)="-"), "Missing", IF( IF(ISNUMBER(C7), C7, IFERROR(TIMEVALUE(C7), 0)) < TIME(8,30,0), "Early", IF( AND( IF(ISNUMBER(C7), C7, IFERROR(TIMEVALUE(C7), 0)) >= TIME(8,30,0), IF(ISNUMBER(C7), C7, IFERROR(TIMEVALUE(C7), 0)) <= TIME(8,50,0), (IF(ISNUMBER(D7), D7, IFERROR(TIMEVALUE(D7), 0)) - IF(ISNUMBER(C7), C7, IFERROR(TIMEVALUE(C7), 0))) >= TIME(8,0,0) ), "On Time", "Late" ) ) ) ) -> On Time | I7: 480
A8: Sheet 20 | B8: 2026-01-09 | C8: 8:48 AM | D8: 4:52 PM | E8: =IF(OR(C8="Absent",D8="Absent",C8="",D8=""),"", (D8-C8)*1440) -> 484 | F8: =IF(OR(C8="",C8="Absent"),"", MAX(0,(C8 - TIME(8,50,0))*1440)) -> 0 | G8: =IF(C8="","", MAX(0,480 - E8)) -> 0 | H8: =IF(OR(TRIM(C8)="Absent", TRIM(C8)="ABSENT"), "Absent", IF(OR(TRIM(C8)="", TRIM(C8)="-", TRIM(D8)="", TRIM(D8)="-"), "Missing", IF( IF(ISNUMBER(C8), C8, IFERROR(TIMEVALUE(C8), 0)) < TIME(8,30,0), "Early", IF( AND( IF(ISNUMBER(C8), C8, IFERROR(TIMEVALUE(C8), 0)) >= TIME(8,30,0), IF(ISNUMBER(C8), C8, IFERROR(TIMEVALUE(C8), 0)) <= TIME(8,50,0), (IF(ISNUMBER(D8), D8, IFERROR(TIMEVALUE(D8), 0)) - IF(ISNUMBER(C8), C8, IFERROR(TIMEVALUE(C8), 0))) >= TIME(8,0,0) ), "On Time", "Late" ) ) ) ) -> On Time | I8: 480
A9: Sheet 20 | B9: 2026-01-12 | C9: 8:45 AM | D9: 4:50 PM | E9: =IF(OR(C9="Absent",D9="Absent",C9="",D9=""),"", (D9-C9)*1440) -> 485 | F9: =IF(OR(C9="",C9="Absent"),"", MAX(0,(C9 - TIME(8,50,0))*1440)) -> 0 | G9: =IF(C9="","", MAX(0,480 - E9)) -> 0 | H9: =IF(OR(TRIM(C9)="Absent", TRIM(C9)="ABSENT"), "Absent", IF(OR(TRIM(C9)="", TRIM(C9)="-", TRIM(D9)="", TRIM(D9)="-"), "Missing", IF( IF(ISNUMBER(C9), C9, IFERROR(TIMEVALUE(C9), 0)) < TIME(8,30,0), "Early", IF( AND( IF(ISNUMBER(C9), C9, IFERROR(TIMEVALUE(C9), 0)) >= TIME(8,30,0), IF(ISNUMBER(C9), C9, IFERROR(TIMEVALUE(C9), 0)) <= TIME(8,50,0), (IF(ISNUMBER(D9), D9, IFERROR(TIMEVALUE(D9), 0)) - IF(ISNUMBER(C9), C9, IFERROR(TIMEVALUE(C9), 0))) >= TIME(8,0,0) ), "On Time", "Late" ) ) ) ) -> On Time | I9: 480
A10: Sheet 20 | B10: 2026-01-13 | C10: 8:45 AM | D10: 4:38 PM | E10: =IF(OR(C10="Absent",D10="Absent",C10="",D10=""),"", (D10-C10)*1440) -> 473 | F10: =IF(OR(C10="",C10="Absent"),"", MAX(0,(C10 - TIME(8,50,0))*1440)) -> 0 | G10: =IF(C10="","", MAX(0,480 - E10)) -> 7 | H10: =IF(OR(TRIM(C10)="Absent", TRIM(C10)="ABSENT"), "Absent", IF(OR(TRIM(C10)="", TRIM(C10)="-", TRIM(D10)="", TRIM(D10)="-"), "Missing", IF( IF(ISNUMBER(C10), C10, IFERROR(TIMEVALUE(C10), 0)) < TIME(8,30,0), "Early", IF( AND( IF(ISNUMBER(C10), C10, IFERROR(TIMEVALUE(C10), 0)) >= TIME(8,30,0), IF(ISNUMBER(C10), C10, IFERROR(TIMEVALUE(C10), 0)) <= TIME(8,50,0), (IF(ISNUMBER(D10), D10, IFERROR(TIMEVALUE(D10), 0)) - IF(ISNUMBER(C10), C10, IFERROR(TIMEVALUE(C10), 0))) >= TIME(8,0,0) ), "On Time", "Late" ) ) ) ) -> Late | I10: 480
A11: Sheet 20 | B11: 2026-01-14 | C11: 8:45 AM | D11: 4:50 PM | E11: =IF(OR(C11="Absent",D11="Absent",C11="",D11=""),"", (D11-C11)*1440) -> 485 | F11: =IF(OR(C11="",C11="Absent"),"", MAX(0,(C11 - TIME(8,50,0))*1440)) -> 0 | G11: =IF(C11="","", MAX(0,480 - E11)) -> 0 | H11: =IF(OR(TRIM(C11)="Absent", TRIM(C11)="ABSENT"), "Absent", IF(OR(TRIM(C11)="", TRIM(C11)="-", TRIM(D11)="", TRIM(D11)="-"), "Missing", IF( IF(ISNUMBER(C11), C11, IFERROR(TIMEVALUE(C11), 0)) < TIME(8,30,0), "Early", IF( AND( IF(ISNUMBER(C11), C11, IFERROR(TIMEVALUE(C11), 0)) >= TIME(8,30,0), IF(ISNUMBER(C11), C11, IFERROR(TIMEVALUE(C11), 0)) <= TIME(8,50,0), (IF(ISNUMBER(D11), D11, IFERROR(TIMEVALUE(D11), 0)) - IF(ISNUMBER(C11), C11, IFERROR(TIMEVALUE(C11), 0))) >= TIME(8,0,0) ), "On Time", "Late" ) ) ) ) -> On Time | I11: 480
A12: Sheet 20 | B12: 2026-01-15 | C12: 8:49 AM | D12: 4:38 PM | E12: =IF(OR(C12="Absent",D12="Absent",C12="",D12=""),"", (D12-C12)*1440) -> 469 | F12: =IF(OR(C12="",C12="Absent"),"", MAX(0,(C12 - TIME(8,50,0))*1440)) -> 0 | G12: =IF(C12="","", MAX(0,480 - E12)) -> 11 | H12: =IF(OR(TRIM(C12)="Absent", TRIM(C12)="ABSENT"), "Absent", IF(OR(TRIM(C12)="", TRIM(C12)="-", TRIM(D12)="", TRIM(D12)="-"), "Missing", IF( IF(ISNUMBER(C12), C12, IFERROR(TIMEVALUE(C12), 0)) < TIME(8,30,0), "Early", IF( AND( IF(ISNUMBER(C12), C12, IFERROR(TIMEVALUE(C12), 0)) >= TIME(8,30,0), IF(ISNUMBER(C12), C12, IFERROR(TIMEVALUE(C12), 0)) <= TIME(8,50,0), (IF(ISNUMBER(D12), D12, IFERROR(TIMEVALUE(D12), 0)) - IF(ISNUMBER(C12), C12, IFERROR(TIMEVALUE(C12), 0))) >= TIME(8,0,0) ), "On Time", "Late" ) ) ) ) -> Late | I12: 480
A13: Sheet 20 | B13: 2026-01-16 | C13: 8:50 AM | D13: 4:33 PM | E13: =IF(OR(C13="Absent",D13="Absent",C13="",D13=""),"", (D13-C13)*1440) -> 463 | F13: =IF(OR(C13="",C13="Absent"),"", MAX(0,(C13 - TIME(8,50,0))*1440)) -> 0 | G13: =IF(C13="","", MAX(0,480 - E13)) -> 17 | H13: =IF(OR(TRIM(C13)="Absent", TRIM(C13)="ABSENT"), "Absent", IF(OR(TRIM(C13)="", TRIM(C13)="-", TRIM(D13)="", TRIM(D13)="-"), "Missing", IF( IF(ISNUMBER(C13), C13, IFERROR(TIMEVALUE(C13), 0)) < TIME(8,30,0), "Early", IF( AND( IF(ISNUMBER(C13), C13, IFERROR(TIMEVALUE(C13), 0)) >= TIME(8,30,0), IF(ISNUMBER(C13), C13, IFERROR(TIMEVALUE(C13), 0)) <= TIME(8,50,0), (IF(ISNUMBER(D13), D13, IFERROR(TIMEVALUE(D13), 0)) - IF(ISNUMBER(C13), C13, IFERROR(TIMEVALUE(C13), 0))) >= TIME(8,0,0) ), "On Time", "Late" ) ) ) ) -> Late | I13: 480
... A23: Sheet 20 | B23: 2026-01-30 | C23: 8:52 AM | D23: 4:34 PM | E23: =IF(OR(C23="Absent",D23="Absent",C23="",D23=""),"", (D23-C23)*1440) -> 462 | F23: =IF(OR(C23="",C23="Absent"),"", MAX(0,(C23 - TIME(8,50,0))*1440)) -> 2 | G23: =IF(C23="","", MAX(0,480 - E23)) -> 18 | H23: =IF(OR(TRIM(C23)="Absent", TRIM(C23)="ABSENT"), "Absent", IF(OR(TRIM(C23)="", TRIM(C23)="-", TRIM(D23)="", TRIM(D23)="-"), "Missing", IF( IF(ISNUMBER(C23), C23, IFERROR(TIMEVALUE(C23), 0)) < TIME(8,30,0), "Early", IF( AND( IF(ISNUMBER(C23), C23, IFERROR(TIMEVALUE(C23), 0)) >= TIME(8,30,0), IF(ISNUMBER(C23), C23, IFERROR(TIMEVALUE(C23), 0)) <= TIME(8,50,0), (IF(ISNUMBER(D23), D23, IFERROR(TIMEVALUE(D23), 0)) - IF(ISNUMBER(C23), C23, IFERROR(TIMEVALUE(C23), 0))) >= TIME(8,0,0) ), "On Time", "Late" ) ) ) ) -> Late | I23: 480

Sheet Sheet 19
A1: Name | B1: Date | C1: Time In | D1: Time Out | E1: Worked Minutes | F1: Late Minutes | G1: Less Than 8 Hours | H1: Status | I1: Target time | J1: Comments
A2: Sheet 19 | B2: 2026-01-01 | C2: 9:25 AM | D2: 5:21 PM | E2: =IF(OR(C2="Absent",D2="Absent",C2="",D2=""),"", (D2-C2)*1440) -> 476 | F2: =IF(OR(C2="",C2="Absent"),"", MAX(0,(C2 - TIME(8,50,0))*1440)) -> 35 | G2: =IF(C2="","", MAX(0,480 - E2)) -> 4 | H2: =IF(OR(TRIM(C2)="Absent", TRIM(C2)="ABSENT"), "Absent", IF(OR(TRIM(C2)="", TRIM(C2)="-", TRIM(D2)="", TRIM(D2)="-"), "Missing", IF( IF(ISNUMBER(C2), C2, IFERROR(TIMEVALUE(C2), 0)) < TIME(8,30,0), "Early", IF( AND( IF(ISNUMBER(C2), C2, IFERROR(TIMEVALUE(C2), 0)) >= TIME(8,30,0), IF(ISNUMBER(C2), C2, IFERROR(TIMEVALUE(C2), 0)) <= TIME(8,50,0), (IF(ISNUMBER(D2), D2, IFERROR(TIMEVALUE(D2), 0)) - IF(ISNUMBER(C2), C2, IFERROR(TIMEVALUE(C2), 0))) >= TIME(8,0,0) ), "On Time", "Late" ) ) ) ) -> Late | I2: 480
A3: Sheet 19 | B3: 2026-01-02 | C3: 9:15 AM | D3: 5:23 PM | E3: =IF(OR(C3="Absent",D3="Absent",C3="",D3=""),"", (D3-C3)*1440) -> 488 | F3: =IF(OR(C3="",C3="Absent"),"", MAX(0,(C3 - TIME(8,50,0))*1440)) -> 25 | G3: =IF(C3="","", MAX(0,480 - E3)) -> 0 | H3: =IF(OR(TRIM(C3)="Absent", TRIM(C3)="ABSENT"), "Absent", IF(OR(TRIM(C3)="", TRIM(C3)="-", TRIM(D3)="", TRIM(D3)="-"), "Missing", IF( IF(ISNUMBER(C3), C3, IFERROR(TIMEVALUE(C3), 0)) < TIME(8,30,0), "Early", IF( AND( IF(ISNUMBER(C3), C3, IFERROR(TIMEVALUE(C3), 0)) >= TIME(8,30,0), IF(ISNUMBER(C3), C3, IFERROR(TIMEVALUE(C3), 0)) <= TIME(8,50,0), (IF(ISNUMBER(D3), D3, IFERROR(TIMEVALUE(D3), 0)) - IF(ISNUMBER(C3), C3, IFERROR(TIMEVALUE(C3), 0))) >= TIME(8,0,0) ), "On Time", "Late" ) ) ) ) -> Late | I3: 480
A4: Sheet 19 | B4: 2026-01-05 | C4: 8:50 AM | D4: 8:50 AM | E4: =IF(OR(C4="Absent",D4="Absent",C4="",D4=""),"", (D4-C4)*1440) -> 0 | F4: =IF(OR(C4="",C4="Absent"),"", MAX(0,(C4 - TIME(8,50,0))*1440)) -> 0 | G4: =IF(C4="","", MAX(0,480 - E4)) -> 480 | H4: =IF(OR(TRIM(C4)="Absent", TRIM(C4)="ABSENT"), "Absent", IF(OR(TRIM(C4)="", TRIM(C4)="-", TRIM(D4)="", TRIM(D4)="-"), "Missing", IF( IF(ISNUMBER(C4), C4, IFERROR(TIMEVALUE(C4), 0)) < TIME(8,30,0), "Early", IF( AND( IF(ISNUMBER(C4), C4, IFERROR(TIMEVALUE(C4), 0)) >= TIME(8,30,0), IF(ISNUMBER(C4), C4, IFERROR(TIMEVALUE(C4), 0)) <= TIME(8,50,0), (IF(ISNUMBER(D4), D4, IFERROR(TIMEVALUE(D4), 0)) - IF(ISNUMBER(C4), C4, IFERROR(TIMEVALUE(C4), 0))) >= TIME(8,0,0) ), "On Time", "Late" ) ) ) ) -> Late | I4: 480
A5: Sheet 19 | B5: 2026-01-06 | C5: 9:08 AM | D5: 5:19 PM | E5: =IF(OR(C5="Absent",D5="Absent",C5="",D5=""),"", (D5-C5)*1440) -> 491 | F5: =IF(OR(C5="",C5="Absent"),"", MAX(0,(C5 - TIME(8,50,0))*1440)) -> 18 | G5: =IF(C5="","", MAX(0,480 - E5)) -> 0 | H5: =IF(OR(TRIM(C5)="Absent", TRIM(C5)="ABSENT"), "Absent", IF(OR(TRIM(C5)="", TRIM(C5)="-", TRIM(D5)="", TRIM(D5)="-"), "Missing", IF( IF(ISNUMBER(C5), C5, IFERROR(TIMEVALUE(C5), 0)) < TIME(8,30,0), "Early", IF( AND( IF(ISNUMBER(C5), C5, IFERROR(TIMEVALUE(C5), 0)) >= TIME(8,30,0), IF(ISNUMBER(C5), C5, IFERROR(TIMEVALUE(C5), 0)) <= TIME(8,50,0), (IF(ISNUMBER(D5), D5, IFERROR(TIMEVALUE(D5), 0)) - IF(ISNUMBER(C5), C5, IFERROR(TIMEVALUE(C5), 0))) >= TIME(8,0,0) ), "On Time", "Late" ) ) ) ) -> Late | I5: 480
A6: Sheet 19 | B6: 2026-01-07 | C6: 9:14 AM | D6: 5:32 PM | E6: =IF(OR(C6="Absent",D6="Absent",C6="",D6=""),"", (D6-C6)*1440) -> 498 | F6: =IF(OR(C6="",C6="Absent"),"", MAX(0,(C6 - TIME(8,50,0))*1440)) -> 24 | G6: =IF(C6="","", MAX(0,480 - E6)) -> 0 | H6: =IF(OR(TRIM(C6)="Absent", TRIM(C6)="ABSENT"), "Absent", IF(OR(TRIM(C6)="", TRIM(C6)="-", TRIM(D6)="", TRIM(D6)="-"), "Missing", IF( IF(ISNUMBER(C6), C6, IFERROR(TIMEVALUE(C6), 0)) < TIME(8,30,0), "Early", IF( AND( IF(ISNUMBER(C6), C6, IFERROR(TIMEVALUE(C6), 0)) >= TIME(8,30,0), IF(ISNUMBER(C6), C6, IFERROR(TIMEVALUE(C6), 0)) <= TIME(8,50,0), (IF(ISNUMBER(D6), D6, IFERROR(TIMEVALUE(D6), 0)) - IF(ISNUMBER(C6), C6, IFERROR(TIMEVALUE(C6), 0))) >= TIME(8,0,0) ), "On Time", "Late" ) ) ) ) -> Late | I6: 480
A7: Sheet 19 | B7: 2026-01-08 | C7: 9:08 AM | D7: 5:12 PM | E7: =IF(OR(C7="Absent",D7="Absent",C7="",D7=""),"", (D7-C7)*1440) -> 484 | F7: =IF(OR(C7="",C7="Absent"),"", MAX(0,(C7 - TIME(8,50,0))*1440)) -> 18 | G7: =IF(C7="","", MAX(0,480 - E7)) -> 0 | H7: =IF(OR(TRIM(C7)="Absent", TRIM(C7)="ABSENT"), "Absent", IF(OR(TRIM(C7)="", TRIM(C7)="-", TRIM(D7)="", TRIM(D7)="-"), "Missing", IF( IF(ISNUMBER(C7), C7, IFERROR(TIMEVALUE(C7), 0)) < TIME(8,30,0), "Early", IF( AND( IF(ISNUMBER(C7), C7, IFERROR(TIMEVALUE(C7), 0)) >= TIME(8,30,0), IF(ISNUMBER(C7), C7, IFERROR(TIMEVALUE(C7), 0)) <= TIME(8,50,0), (IF(ISNUMBER(D7), D7, IFERROR(TIMEVALUE(D7), 0)) - IF(ISNUMBER(C7), C7, IFERROR(TIMEVALUE(C7), 0))) >= TIME(8,0,0) ), "On Time", "Late" ) ) ) ) -> Late | I7: 480
A8: Sheet 19 | B8: 2026-01-09 | C8: 9:07 AM | D8: 5:34 PM | E8: =IF(OR(C8="Absent",D8="Absent",C8="",D8=""),"", (D8-C8)*1440) -> 507 | F8: =IF(OR(C8="",C8="Absent"),"", MAX(0,(C8 - TIME(8,50,0))*1440)) -> 17 | G8: =IF(C8="","", MAX(0,480 - E8)) -> 0 | H8: =IF(OR(TRIM(C8)="Absent", TRIM(C8)="ABSENT"), "Absent", IF(OR(TRIM(C8)="", TRIM(C8)="-", TRIM(D8)="", TRIM(D8)="-"), "Missing", IF( IF(ISNUMBER(C8), C8, IFERROR(TIMEVALUE(C8), 0)) < TIME(8,30,0), "Early", IF( AND( IF(ISNUMBER(C8), C8, IFERROR(TIMEVALUE(C8), 0)) >= TIME(8,30,0), IF(ISNUMBER(C8), C8, IFERROR(TIMEVALUE(C8), 0)) <= TIME(8,50,0), (IF(ISNUMBER(D8), D8, IFERROR(TIMEVALUE(D8), 0)) - IF(ISNUMBER(C8), C8, IFERROR(TIMEVALUE(C8), 0))) >= TIME(8,0,0) ), "On Time", "Late" ) ) ) ) -> Late | I8: 480
A9: Sheet 19 | B9: 2026-01-12 | C9: 9:05 AM | D9: 5:19 PM | E9: =IF(OR(C9="Absent",D9="Absent",C9="",D9=""),"", (D9-C9)*1440) -> 494 | F9: =IF(OR(C9="",C9="Absent"),"", MAX(0,(C9 - TIME(8,50,0))*1440)) -> 15 | G9: =IF(C9="","", MAX(0,480 - E9)) -> 0 | H9: =IF(OR(TRIM(C9)="Absent", TRIM(C9)="ABSENT"), "Absent", IF(OR(TRIM(C9)="", TRIM(C9)="-", TRIM(D9)="", TRIM(D9)="-"), "Missing", IF( IF(ISNUMBER(C9), C9, IFERROR(TIMEVALUE(C9), 0)) < TIME(8,30,0), "Early", IF( AND( IF(ISNUMBER(C9), C9, IFERROR(TIMEVALUE(C9), 0)) >= TIME(8,30,0), IF(ISNUMBER(C9), C9, IFERROR(TIMEVALUE(C9), 0)) <= TIME(8,50,0), (IF(ISNUMBER(D9), D9, IFERROR(TIMEVALUE(D9), 0)) - IF(ISNUMBER(C9), C9, IFERROR(TIMEVALUE(C9), 0))) >= TIME(8,0,0) ), "On Time", "Late" ) ) ) ) -> Late | I9: 480
A10: Sheet 19 | B10: 2026-01-13 | C10: 9:01 AM | D10: 5:21 PM | E10: =IF(OR(C10="Absent",D10="Absent",C10="",D10=""),"", (D10-C10)*1440) -> 500 | F10: =IF(OR(C10="",C10="Absent"),"", MAX(0,(C10 - TIME(8,50,0))*1440)) -> 11 | G10: =IF(C10="","", MAX(0,480 - E10)) -> 0 | H10: =IF(OR(TRIM(C10)="Absent", TRIM(C10)="ABSENT"), "Absent", IF(OR(TRIM(C10)="", TRIM(C10)="-", TRIM(D10)="", TRIM(D10)="-"), "Missing", IF( IF(ISNUMBER(C10), C10, IFERROR(TIMEVALUE(C10), 0)) < TIME(8,30,0), "Early", IF( AND( IF(ISNUMBER(C10), C10, IFERROR(TIMEVALUE(C10), 0)) >= TIME(8,30,0), IF(ISNUMBER(C10), C10, IFERROR(TIMEVALUE(C10), 0)) <= TIME(8,50,0), (IF(ISNUMBER(D10), D10, IFERROR(TIMEVALUE(D10), 0)) - IF(ISNUMBER(C10), C10, IFERROR(TIMEVALUE(C10), 0))) >= TIME(8,0,0) ), "On Time", "Late" ) ) ) ) -> Late | I10: 480
A11: Sheet 19 | B11: 2026-01-14 | C11: 9:55 AM | D11: - | E11: =IF(OR(C11="Absent",D11="Absent",C11="",D11=""),"", (D11-C11)*1440) -> #VALUE! | F11: =IF(OR(C11="",C11="Absent"),"", MAX(0,(C11 - TIME(8,50,0))*1440)) -> 65 | G11: =IF(C11="","", MAX(0,480 - E11)) -> #VALUE! | H11: =IF(OR(TRIM(C11)="Absent", TRIM(C11)="ABSENT"), "Absent", IF(OR(TRIM(C11)="", TRIM(C11)="-", TRIM(D11)="", TRIM(D11)="-"), "Missing", IF( IF(ISNUMBER(C11), C11, IFERROR(TIMEVALUE(C11), 0)) < TIME(8,30,0), "Early", IF( AND( IF(ISNUMBER(C11), C11, IFERROR(TIMEVALUE(C11), 0)) >= TIME(8,30,0), IF(ISNUMBER(C11), C11, IFERROR(TIMEVALUE(C11), 0)) <= TIME(8,50,0), (IF(ISNUMBER(D11), D11, IFERROR(TIMEVALUE(D11), 0)) - IF(ISNUMBER(C11), C11, IFERROR(TIMEVALUE(C11), 0))) >= TIME(8,0,0) ), "On Time", "Late" ) ) ) ) -> Missing | I11: 480
A12: Sheet 19 | B12: 2026-01-15 | C12: 9:24 AM | D12: 5:40 PM | E12: =IF(OR(C12="Absent",D12="Absent",C12="",D12=""),"", (D12-C12)*1440) -> 496 | F12: =IF(OR(C12="",C12="Absent"),"", MAX(0,(C12 - TIME(8,50,0))*1440)) -> 34 | G12: =IF(C12="","", MAX(0,480 - E12)) -> 0 | H12: =IF(OR(TRIM(C12)="Absent", TRIM(C12)="ABSENT"), "Absent", IF(OR(TRIM(C12)="", TRIM(C12)="-", TRIM(D12)="", TRIM(D12)="-"), "Missing", IF( IF(ISNUMBER(C12), C12, IFERROR(TIMEVALUE(C12), 0)) < TIME(8,30,0), "Early", IF( AND( IF(ISNUMBER(C12), C12, IFERROR(TIMEVALUE(C12), 0)) >= TIME(8,30,0), IF(ISNUMBER(C12), C12, IFERROR(TIMEVALUE(C12), 0)) <= TIME(8,50,0), (IF(ISNUMBER(D12), D12, IFERROR(TIMEVALUE(D12), 0)) - IF(ISNUMBER(C12), C12, IFERROR(TIMEVALUE(C12), 0))) >= TIME(8,0,0) ), "On Time", "Late" ) ) ) ) -> Late | I12: 480
A13: Sheet 19 | B13: 2026-01-16 | C13: 9:18 AM | D13: 5:47 PM | E13: =IF(OR(C13="Absent",D13="Absent",C13="",D13=""),"", (D13-C13)*1440) -> 509 | F13: =IF(OR(C13="",C13="Absent"),"", MAX(0,(C13 - TIME(8,50,0))*1440)) -> 28 | G13: =IF(C13="","", MAX(0,480 - E13)) -> 0 | H13: =IF(OR(TRIM(C13)="Absent", TRIM(C13)="ABSENT"), "Absent", IF(OR(TRIM(C13)="", TRIM(C13)="-", TRIM(D13)="", TRIM(D13)="-"), "Missing", IF( IF(ISNUMBER(C13), C13, IFERROR(TIMEVALUE(C13), 0)) < TIME(8,30,0), "Early", IF( AND( IF(ISNUMBER(C13), C13, IFERROR(TIMEVALUE(C13), 0)) >= TIME(8,30,0), IF(ISNUMBER(C13), C13, IFERROR(TIMEVALUE(C13), 0)) <= TIME(8,50,0), (IF(ISNUMBER(D13), D13, IFERROR(TIMEVALUE(D13), 0)) - IF(ISNUMBER(C13), C13, IFERROR(TIMEVALUE(C13), 0))) >= TIME(8,0,0) ), "On Time", "Late" ) ) ) ) -> Late | I13: 480
... A23: Sheet 19 | B23: 2026-01-30 | C23: 9:33 AM | D23: 5:32 PM | E23: =IF(OR(C23="Absent",D23="Absent",C23="",D23=""),"", (D23-C23)*1440) -> 479 | F23: =IF(OR(C23="",C23="Absent"),"", MAX(0,(C23 - TIME(8,50,0))*1440)) -> 43 | G23: =IF(C23="","", MAX(0,480 - E23)) -> 1 | H23: =IF(OR(TRIM(C23)="Absent", TRIM(C23)="ABSENT"), "Absent", IF(OR(TRIM(C23)="", TRIM(C23)="-", TRIM(D23)="", TRIM(D23)="-"), "Missing", IF( IF(ISNUMBER(C23), C23, IFERROR(TIMEVALUE(C23), 0)) < TIME(8,30,0), "Early", IF( AND( IF(ISNUMBER(C23), C23, IFERROR(TIMEVALUE(C23), 0)) >= TIME(8,30,0), IF(ISNUMBER(C23), C23, IFERROR(TIMEVALUE(C23), 0)) <= TIME(8,50,0), (IF(ISNUMBER(D23), D23, IFERROR(TIMEVALUE(D23), 0)) - IF(ISNUMBER(C23), C23, IFERROR(TIMEVALUE(C23), 0))) >= TIME(8,0,0) ), "On Time", "Late" ) ) ) ) -> Late | I23: 480

Sheet Sheet 18
A1: Name | B1: Date | C1: Time In | D1: Time Out | E1: Worked Minutes | F1: Late Minutes | G1: Less Than 8 Hours | H1: Status | I1: Target time | J1: Comments
A2: Sheet 18 | B2: 2026-01-01 | C2: 8:36 AM | D2: 4:57 PM | E2: =IF(OR(C2="Absent",D2="Absent",C2="",D2=""),"", (D2-C2)*1440) -> 501 | F2: =IF(OR(C2="",C2="Absent"),"", MAX(0,(C2 - TIME(8,50,0))*1440)) -> 0 | G2: =IF(C2="","", MAX(0,480 - E2)) -> 0 | H2: =IF(OR(TRIM(C2)="Absent", TRIM(C2)="ABSENT"), "Absent", IF(OR(TRIM(C2)="", TRIM(C2)="-", TRIM(D2)="", TRIM(D2)="-"), "Missing", IF( IF(ISNUMBER(C2), C2, IFERROR(TIMEVALUE(C2), 0)) < TIME(8,30,0), "Early", IF( AND( IF(ISNUMBER(C2), C2, IFERROR(TIMEVALUE(C2), 0)) >= TIME(8,30,0), IF(ISNUMBER(C2), C2, IFERROR(TIMEVALUE(C2), 0)) <= TIME(8,50,0), (IF(ISNUMBER(D2), D2, IFERROR(TIMEVALUE(D2), 0)) - IF(ISNUMBER(C2), C2, IFERROR(TIMEVALUE(C2), 0))) >= TIME(8,0,0) ), "On Time", "Late" ) ) ) ) -> On Time | I2: 480
A3: Sheet 18 | B3: 2026-01-02 | C3: 8:30 AM | D3: 5:24 PM | E3: =IF(OR(C3="Absent",D3="Absent",C3="",D3=""),"", (D3-C3)*1440) -> 534 | F3: =IF(OR(C3="",C3="Absent"),"", MAX(0,(C3 - TIME(8,50,0))*1440)) -> 0 | G3: =IF(C3="","", MAX(0,480 - E3)) -> 0 | H3: =IF(OR(TRIM(C3)="Absent", TRIM(C3)="ABSENT"), "Absent", IF(OR(TRIM(C3)="", TRIM(C3)="-", TRIM(D3)="", TRIM(D3)="-"), "Missing", IF( IF(ISNUMBER(C3), C3, IFERROR(TIMEVALUE(C3), 0)) < TIME(8,30,0), "Early", IF( AND( IF(ISNUMBER(C3), C3, IFERROR(TIMEVALUE(C3), 0)) >= TIME(8,30,0), IF(ISNUMBER(C3), C3, IFERROR(TIMEVALUE(C3), 0)) <= TIME(8,50,0), (IF(ISNUMBER(D3), D3, IFERROR(TIMEVALUE(D3), 0)) - IF(ISNUMBER(C3), C3, IFERROR(TIMEVALUE(C3), 0))) >= TIME(8,0,0) ), "On Time", "Late" ) ) ) ) -> On Time | I3: 480
A4: Sheet 18 | B4: 2026-01-05 | C4: 8:20 AM | D4: 5:44 PM | E4: =IF(OR(C4="Absent",D4="Absent",C4="",D4=""),"", (D4-C4)*1440) -> 564 | F4: =IF(OR(C4="",C4="Absent"),"", MAX(0,(C4 - TIME(8,50,0))*1440)) -> 0 | G4: =IF(C4="","", MAX(0,480 - E4)) -> 0 | H4: =IF(OR(TRIM(C4)="Absent", TRIM(C4)="ABSENT"), "Absent", IF(OR(TRIM(C4)="", TRIM(C4)="-", TRIM(D4)="", TRIM(D4)="-"), "Missing", IF( IF(ISNUMBER(C4), C4, IFERROR(TIMEVALUE(C4), 0)) < TIME(8,30,0), "Early", IF( AND( IF(ISNUMBER(C4), C4, IFERROR(TIMEVALUE(C4), 0)) >= TIME(8,30,0), IF(ISNUMBER(C4), C4, IFERROR(TIMEVALUE(C4), 0)) <= TIME(8,50,0), (IF(ISNUMBER(D4), D4, IFERROR(TIMEVALUE(D4), 0)) - IF(ISNUMBER(C4), C4, IFERROR(TIMEVALUE(C4), 0))) >= TIME(8,0,0) ), "On Time", "Late" ) ) ) ) -> Early | I4: 480
A5: Sheet 18 | B5: 2026-01-06 | C5: 8:56 AM | D5: 5:44 PM | E5: =IF(OR(C5="Absent",D5="Absent",C5="",D5=""),"", (D5-C5)*1440) -> 528 | F5: =IF(OR(C5="",C5="Absent"),"", MAX(0,(C5 - TIME(8,50,0))*1440)) -> 6 | G5: =IF(C5="","", MAX(0,480 - E5)) -> 0 | H5: =IF(OR(TRIM(C5)="Absent", TRIM(C5)="ABSENT"), "Absent", IF(OR(TRIM(C5)="", TRIM(C5)="-", TRIM(D5)="", TRIM(D5)="-"), "Missing", IF( IF(ISNUMBER(C5), C5, IFERROR(TIMEVALUE(C5), 0)) < TIME(8,30,0), "Early", IF( AND( IF(ISNUMBER(C5), C5, IFERROR(TIMEVALUE(C5), 0)) >= TIME(8,30,0), IF(ISNUMBER(C5), C5, IFERROR(TIMEVALUE(C5), 0)) <= TIME(8,50,0), (IF(ISNUMBER(D5), D5, IFERROR(TIMEVALUE(D5), 0)) - IF(ISNUMBER(C5), C5, IFERROR(TIMEVALUE(C5), 0))) >= TIME(8,0,0) ), "On Time", "Late" ) ) ) ) -> Late | I5: 480
A6: Sheet 18 | B6: 2026-01-07 | C6: 8:28 AM | D6: 6:00 PM | E6: =IF(OR(C6="Absent",D6="Absent",C6="",D6=""),"", (D6-C6)*1440) -> 572 | F6: =IF(OR(C6="",C6="Absent"),"", MAX(0,(C6 - TIME(8,50,0))*1440)) -> 0 | G6: =IF(C6="","", MAX(0,480 - E6)) -> 0 | H6: =IF(OR(TRIM(C6)="Absent", TRIM(C6)="ABSENT"), "Absent", IF(OR(TRIM(C6)="", TRIM(C6)="-", TRIM(D6)="", TRIM(D6)="-"), "Missing", IF( IF(ISNUMBER(C6), C6, IFERROR(TIMEVALUE(C6), 0)) < TIME(8,30,0), "Early", IF( AND( IF(ISNUMBER(C6), C6, IFERROR(TIMEVALUE(C6), 0)) >= TIME(8,30,0), IF(ISNUMBER(C6), C6, IFERROR(TIMEVALUE(C6), 0)) <= TIME(8,50,0), (IF(ISNUMBER(D6), D6, IFERROR(TIMEVALUE(D6), 0)) - IF(ISNUMBER(C6), C6, IFERROR(TIMEVALUE(C6), 0))) >= TIME(8,0,0) ), "On Time", "Late" ) ) ) ) -> Early | I6: 480
A7: Sheet 18 | B7: 2026-01-08 | C7: 8:35 AM | D7: 5:31 PM | E7: =IF(OR(C7="Absent",D7="Absent",C7="",D7=""),"", (D7-C7)*1440) -> 536 | F7: =IF(OR(C7="",C7="Absent"),"", MAX(0,(C7 - TIME(8,50,0))*1440)) -> 0 | G7: =IF(C7="","", MAX(0,480 - E7)) -> 0 | H7: =IF(OR(TRIM(C7)="Absent", TRIM(C7)="ABSENT"), "Absent", IF(OR(TRIM(C7)="", TRIM(C7)="-", TRIM(D7)="", TRIM(D7)="-"), "Missing", IF( IF(ISNUMBER(C7), C7, IFERROR(TIMEVALUE(C7), 0)) < TIME(8,30,0), "Early", IF( AND( IF(ISNUMBER(C7), C7, IFERROR(TIMEVALUE(C7), 0)) >= TIME(8,30,0), IF(ISNUMBER(C7), C7, IFERROR(TIMEVALUE(C7), 0)) <= TIME(8,50,0), (IF(ISNUMBER(D7), D7, IFERROR(TIMEVALUE(D7), 0)) - IF(ISNUMBER(C7), C7, IFERROR(TIMEVALUE(C7), 0))) >= TIME(8,0,0) ), "On Time", "Late" ) ) ) ) -> On Time | I7: 480
A8: Sheet 18 | B8: 2026-01-09 | C8: 8:44 AM | D8: 4:21 PM | E8: =IF(OR(C8="Absent",D8="Absent",C8="",D8=""),"", (D8-C8)*1440) -> 457 | F8: =IF(OR(C8="",C8="Absent"),"", MAX(0,(C8 - TIME(8,50,0))*1440)) -> 0 | G8: =IF(C8="","", MAX(0,480 - E8)) -> 23 | H8: =IF(OR(TRIM(C8)="Absent", TRIM(C8)="ABSENT"), "Absent", IF(OR(TRIM(C8)="", TRIM(C8)="-", TRIM(D8)="", TRIM(D8)="-"), "Missing", IF( IF(ISNUMBER(C8), C8, IFERROR(TIMEVALUE(C8), 0)) < TIME(8,30,0), "Early", IF( AND( IF(ISNUMBER(C8), C8, IFERROR(TIMEVALUE(C8), 0)) >= TIME(8,30,0), IF(ISNUMBER(C8), C8, IFERROR(TIMEVALUE(C8), 0)) <= TIME(8,50,0), (IF(ISNUMBER(D8), D8, IFERROR(TIMEVALUE(D8), 0)) - IF(ISNUMBER(C8), C8, IFERROR(TIMEVALUE(C8), 0))) >= TIME(8,0,0) ), "On Time", "Late" ) ) ) ) -> Late | I8: 480
A9: Sheet 18 | B9: 2026-01-12 | C9: 8:30 AM | D9: 4:46 PM | E9: =IF(OR(C9="Absent",D9="Absent",C9="",D9=""),"", (D9-C9)*1440) -> 496 | F9: =IF(OR(C9="",C9="Absent"),"", MAX(0,(C9 - TIME(8,50,0))*1440)) -> 0 | G9: =IF(C9="","", MAX(0,480 - E9)) -> 0 | H9: =IF(OR(TRIM(C9)="Absent", TRIM(C9)="ABSENT"), "Absent", IF(OR(TRIM(C9)="", TRIM(C9)="-", TRIM(D9)="", TRIM(D9)="-"), "Missing", IF( IF(ISNUMBER(C9), C9, IFERROR(TIMEVALUE(C9), 0)) < TIME(8,30,0), "Early", IF( AND( IF(ISNUMBER(C9), C9, IFERROR(TIMEVALUE(C9), 0)) >= TIME(8,30,0), IF(ISNUMBER(C9), C9, IFERROR(TIMEVALUE(C9), 0)) <= TIME(8,50,0), (IF(ISNUMBER(D9), D9, IFERROR(TIMEVALUE(D9), 0)) - IF(ISNUMBER(C9), C9, IFERROR(TIMEVALUE(C9), 0))) >= TIME(8,0,0) ), "On Time", "Late" ) ) ) ) -> On Time | I9: 480
A10: Sheet 18 | B10: 2026-01-13 | C10: 8:24 AM | D10: 5:39 PM | E10: =IF(OR(C10="Absent",D10="Absent",C10="",D10=""),"", (D10-C10)*1440) -> 555 | F10: =IF(OR(C10="",C10="Absent"),"", MAX(0,(C10 - TIME(8,50,0))*1440)) -> 0 | G10: =IF(C10="","", MAX(0,480 - E10)) -> 0 | H10: =IF(OR(TRIM(C10)="Absent", TRIM(C10)="ABSENT"), "Absent", IF(OR(TRIM(C10)="", TRIM(C10)="-", TRIM(D10)="", TRIM(D10)="-"), "Missing", IF( IF(ISNUMBER(C10), C10, IFERROR(TIMEVALUE(C10), 0)) < TIME(8,30,0), "Early", IF( AND( IF(ISNUMBER(C10), C10, IFERROR(TIMEVALUE(C10), 0)) >= TIME(8,30,0), IF(ISNUMBER(C10), C10, IFERROR(TIMEVALUE(C10), 0)) <= TIME(8,50,0), (IF(ISNUMBER(D10), D10, IFERROR(TIMEVALUE(D10), 0)) - IF(ISNUMBER(C10), C10, IFERROR(TIMEVALUE(C10), 0))) >= TIME(8,0,0) ), "On Time", "Late" ) ) ) ) -> Early | I10: 480
A11: Sheet 18 | B11: 2026-01-14 | C11: 8:26 AM | D11: 5:52 PM | E11: =IF(OR(C11="Absent",D11="Absent",C11="",D11=""),"", (D11-C11)*1440) -> 566 | F11: =IF(OR(C11="",C11="Absent"),"", MAX(0,(C11 - TIME(8,50,0))*1440)) -> 0 | G11: =IF(C11="","", MAX(0,480 - E11)) -> 0 | H11: =IF(OR(TRIM(C11)="Absent", TRIM(C11)="ABSENT"), "Absent", IF(OR(TRIM(C11)="", TRIM(C11)="-", TRIM(D11)="", TRIM(D11)="-"), "Missing", IF( IF(ISNUMBER(C11), C11, IFERROR(TIMEVALUE(C11), 0)) < TIME(8,30,0), "Early", IF( AND( IF(ISNUMBER(C11), C11, IFERROR(TIMEVALUE(C11), 0)) >= TIME(8,30,0), IF(ISNUMBER(C11), C11, IFERROR(TIMEVALUE(C11), 0)) <= TIME(8,50,0), (IF(ISNUMBER(D11), D11, IFERROR(TIMEVALUE(D11), 0)) - IF(ISNUMBER(C11), C11, IFERROR(TIMEVALUE(C11), 0))) >= TIME(8,0,0) ), "On Time", "Late" ) ) ) ) -> Early | I11: 480
A12: Sheet 18 | B12: 2026-01-15 | C12: 8:28 AM | D12: 5:37 PM | E12: =IF(OR(C12="Absent",D12="Absent",C12="",D12=""),"", (D12-C12)*1440) -> 549 | F12: =IF(OR(C12="",C12="Absent"),"", MAX(0,(C12 - TIME(8,50,0))*1440)) -> 0 | G12: =IF(C12="","", MAX(0,480 - E12)) -> 0 | H12: =IF(OR(TRIM(C12)="Absent", TRIM(C12)="ABSENT"), "Absent", IF(OR(TRIM(C12)="", TRIM(C12)="-", TRIM(D12)="", TRIM(D12)="-"), "Missing", IF( IF(ISNUMBER(C12), C12, IFERROR(TIMEVALUE(C12), 0)) < TIME(8,30,0), "Early", IF( AND( IF(ISNUMBER(C12), C12, IFERROR(TIMEVALUE(C12), 0)) >= TIME(8,30,0), IF(ISNUMBER(C12), C12, IFERROR(TIMEVALUE(C12), 0)) <= TIME(8,50,0), (IF(ISNUMBER(D12), D12, IFERROR(TIMEVALUE(D12), 0)) - IF(ISNUMBER(C12), C12, IFERROR(TIMEVALUE(C12), 0))) >= TIME(8,0,0) ), "On Time", "Late" ) ) ) ) -> Early | I12: 480
A13: Sheet 18 | B13: 2026-01-16 | C13: 8:33 AM | D13: 5:01 PM | E13: =IF(OR(C13="Absent",D13="Absent",C13="",D13=""),"", (D13-C13)*1440) -> 508 | F13: =IF(OR(C13="",C13="Absent"),"", MAX(0,(C13 - TIME(8,50,0))*1440)) -> 0 | G13: =IF(C13="","", MAX(0,480 - E13)) -> 0 | H13: =IF(OR(TRIM(C13)="Absent", TRIM(C13)="ABSENT"), "Absent", IF(OR(TRIM(C13)="", TRIM(C13)="-", TRIM(D13)="", TRIM(D13)="-"), "Missing", IF( IF(ISNUMBER(C13), C13, IFERROR(TIMEVALUE(C13), 0)) < TIME(8,30,0), "Early", IF( AND( IF(ISNUMBER(C13), C13, IFERROR(TIMEVALUE(C13), 0)) >= TIME(8,30,0), IF(ISNUMBER(C13), C13, IFERROR(TIMEVALUE(C13), 0)) <= TIME(8,50,0), (IF(ISNUMBER(D13), D13, IFERROR(TIMEVALUE(D13), 0)) - IF(ISNUMBER(C13), C13, IFERROR(TIMEVALUE(C13), 0))) >= TIME(8,0,0) ), "On Time", "Late" ) ) ) ) -> On Time | I13: 480
... A23: Sheet 18 | B23: 2026-01-30 | C23: Absent | D23: - | E23: =IF(OR(C23="Absent",D23="Absent",C23="",D23=""),"", (D23-C23)*1440) | F23: =IF(OR(C23="",C23="Absent"),"", MAX(0,(C23 - TIME(8,50,0))*1440)) | G23: =IF(C23="","", MAX(0,480 - E23)) -> #VALUE! | H23: =IF(OR(TRIM(C23)="Absent", TRIM(C23)="ABSENT"), "Absent", IF(OR(TRIM(C23)="", TRIM(C23)="-", TRIM(D23)="", TRIM(D23)="-"), "Missing", IF( IF(ISNUMBER(C23), C23, IFERROR(TIMEVALUE(C23), 0)) < TIME(8,30,0), "Early", IF( AND( IF(ISNUMBER(C23), C23, IFERROR(TIMEVALUE(C23), 0)) >= TIME(8,30,0), IF(ISNUMBER(C23), C23, IFERROR(TIMEVALUE(C23), 0)) <= TIME(8,50,0), (IF(ISNUMBER(D23), D23, IFERROR(TIMEVALUE(D23), 0)) - IF(ISNUMBER(C23), C23, IFERROR(TIMEVALUE(C23), 0))) >= TIME(8,0,0) ), "On Time", "Late" ) ) ) ) -> Absent | I23: 480

Sheet Sheet 17
A1: Name | B1: Date | C1: Time In | D1: Time Out | E1: Worked Minutes | F1: Late Minutes | G1: Less Than 8 Hours | H1: Status | I1: Target time | J1: Comments
A2: Sheet 17 | B2: 2026-01-01 | C2: 8:25 AM | D2: - | E2: =IF(OR(C2="Absent",D2="Absent",C2="",D2=""),"", (D2-C2)*1440) -> #VALUE! | F2: =IF(OR(C2="",C2="Absent"),"", MAX(0,(C2 - TIME(8,50,0))*1440)) -> 0 | G2: =IF(C2="","", MAX(0,480 - E2)) -> #VALUE! | H2: =IF(OR(TRIM(C2)="Absent", TRIM(C2)="ABSENT"), "Absent", IF(OR(TRIM(C2)="", TRIM(C2)="-", TRIM(D2)="", TRIM(D2)="-"), "Missing", IF( IF(ISNUMBER(C2), C2, IFERROR(TIMEVALUE(C2), 0)) < TIME(8,30,0), "Early", IF( AND( IF(ISNUMBER(C2), C2, IFERROR(TIMEVALUE(C2), 0)) >= TIME(8,30,0), IF(ISNUMBER(C2), C2, IFERROR(TIMEVALUE(C2), 0)) <= TIME(8,50,0), (IF(ISNUMBER(D2), D2, IFERROR(TIMEVALUE(D2), 0)) - IF(ISNUMBER(C2), C2, IFERROR(TIMEVALUE(C2), 0))) >= TIME(8,0,0) ), "On Time", "Late" ) ) ) ) -> Missing | I2: 480
A3: Sheet 17 | B3: 2026-01-02 | C3: 8:16 AM | D3: - | E3: =IF(OR(C3="Absent",D3="Absent",C3="",D3=""),"", (D3-C3)*1440) -> #VALUE! | F3: =IF(OR(C3="",C3="Absent"),"", MAX(0,(C3 - TIME(8,50,0))*1440)) -> 0 | G3: =IF(C3="","", MAX(0,480 - E3)) -> #VALUE! | H3: =IF(OR(TRIM(C3)="Absent", TRIM(C3)="ABSENT"), "Absent", IF(OR(TRIM(C3)="", TRIM(C3)="-", TRIM(D3)="", TRIM(D3)="-"), "Missing", IF( IF(ISNUMBER(C3), C3, IFERROR(TIMEVALUE(C3), 0)) < TIME(8,30,0), "Early", IF( AND( IF(ISNUMBER(C3), C3, IFERROR(TIMEVALUE(C3), 0)) >= TIME(8,30,0), IF(ISNUMBER(C3), C3, IFERROR(TIMEVALUE(C3), 0)) <= TIME(8,50,0), (IF(ISNUMBER(D3), D3, IFERROR(TIMEVALUE(D3), 0)) - IF(ISNUMBER(C3), C3, IFERROR(TIMEVALUE(C3), 0))) >= TIME(8,0,0) ), "On Time", "Late" ) ) ) ) -> Missing | I3: 480
A4: Sheet 17 | B4: 2026-01-05 | C4: 8:20 AM | D4: - | E4: =IF(OR(C4="Absent",D4="Absent",C4="",D4=""),"", (D4-C4)*1440) -> #VALUE! | F4: =IF(OR(C4="",C4="Absent"),"", MAX(0,(C4 - TIME(8,50,0))*1440)) -> 0 | G4: =IF(C4="","", MAX(0,480 - E4)) -> #VALUE! | H4: =IF(OR(TRIM(C4)="Absent", TRIM(C4)="ABSENT"), "Absent", IF(OR(TRIM(C4)="", TRIM(C4)="-", TRIM(D4)="", TRIM(D4)="-"), "Missing", IF( IF(ISNUMBER(C4), C4, IFERROR(TIMEVALUE(C4), 0)) < TIME(8,30,0), "Early", IF( AND( IF(ISNUMBER(C4), C4, IFERROR(TIMEVALUE(C4), 0)) >= TIME(8,30,0), IF(ISNUMBER(C4), C4, IFERROR(TIMEVALUE(C4), 0)) <= TIME(8,50,0), (IF(ISNUMBER(D4), D4, IFERROR(TIMEVALUE(D4), 0)) - IF(ISNUMBER(C4), C4, IFERROR(TIMEVALUE(C4), 0))) >= TIME(8,0,0) ), "On Time", "Late" ) ) ) ) -> Missing | I4: 480
A5: Sheet 17 | B5: 2026-01-06 | C5: 8:15 AM | D5: 5:38 PM | E5: =IF(OR(C5="Absent",D5="Absent",C5="",D5=""),"", (D5-C5)*1440) -> 563 | F5: =IF(OR(C5="",C5="Absent"),"", MAX(0,(C5 - TIME(8,50,0))*1440)) -> 0 | G5: =IF(C5="","", MAX(0,480 - E5)) -> 0 | H5: =IF(OR(TRIM(C5)="Absent", TRIM(C5)="ABSENT"), "Absent", IF(OR(TRIM(C5)="", TRIM(C5)="-", TRIM(D5)="", TRIM(D5)="-"), "Missing", IF( IF(ISNUMBER(C5), C5, IFERROR(TIMEVALUE(C5), 0)) < TIME(8,30,0), "Early", IF( AND( IF(ISNUMBER(C5), C5, IFERROR(TIMEVALUE(C5), 0)) >= TIME(8,30,0), IF(ISNUMBER(C5), C5, IFERROR(TIMEVALUE(C5), 0)) <= TIME(8,50,0), (IF(ISNUMBER(D5), D5, IFERROR(TIMEVALUE(D5), 0)) - IF(ISNUMBER(C5), C5, IFERROR(TIMEVALUE(C5), 0))) >= TIME(8,0,0) ), "On Time", "Late" ) ) ) ) -> Early | I5: 480
A6: Sheet 17 | B6: 2026-01-07 | C6: 8:36 AM | D6: 5:39 PM | E6: =IF(OR(C6="Absent",D6="Absent",C6="",D6=""),"", (D6-C6)*1440) -> 543 | F6: =IF(OR(C6="",C6="Absent"),"", MAX(0,(C6 - TIME(8,50,0))*1440)) -> 0 | G6: =IF(C6="","", MAX(0,480 - E6)) -> 0 | H6: =IF(OR(TRIM(C6)="Absent", TRIM(C6)="ABSENT"), "Absent", IF(OR(TRIM(C6)="", TRIM(C6)="-", TRIM(D6)="", TRIM(D6)="-"), "Missing", IF( IF(ISNUMBER(C6), C6, IFERROR(TIMEVALUE(C6), 0)) < TIME(8,30,0), "Early", IF( AND( IF(ISNUMBER(C6), C6, IFERROR(TIMEVALUE(C6), 0)) >= TIME(8,30,0), IF(ISNUMBER(C6), C6, IFERROR(TIMEVALUE(C6), 0)) <= TIME(8,50,0), (IF(ISNUMBER(D6), D6, IFERROR(TIMEVALUE(D6), 0)) - IF(ISNUMBER(C6), C6, IFERROR(TIMEVALUE(C6), 0))) >= TIME(8,0,0) ), "On Time", "Late" ) ) ) ) -> On Time | I6: 480
A7: Sheet 17 | B7: 2026-01-08 | C7: 8:21 AM | D7: 5:40 PM | E7: =IF(OR(C7="Absent",D7="Absent",C7="",D7=""),"", (D7-C7)*1440) -> 559 | F7: =IF(OR(C7="",C7="Absent"),"", MAX(0,(C7 - TIME(8,50,0))*1440)) -> 0 | G7: =IF(C7="","", MAX(0,480 - E7)) -> 0 | H7: =IF(OR(TRIM(C7)="Absent", TRIM(C7)="ABSENT"), "Absent", IF(OR(TRIM(C7)="", TRIM(C7)="-", TRIM(D7)="", TRIM(D7)="-"), "Missing", IF( IF(ISNUMBER(C7), C7, IFERROR(TIMEVALUE(C7), 0)) < TIME(8,30,0), "Early", IF( AND( IF(ISNUMBER(C7), C7, IFERROR(TIMEVALUE(C7), 0)) >= TIME(8,30,0), IF(ISNUMBER(C7), C7, IFERROR(TIMEVALUE(C7), 0)) <= TIME(8,50,0), (IF(ISNUMBER(D7), D7, IFERROR(TIMEVALUE(D7), 0)) - IF(ISNUMBER(C7), C7, IFERROR(TIMEVALUE(C7), 0))) >= TIME(8,0,0) ), "On Time", "Late" ) ) ) ) -> Early | I7: 480
A8: Sheet 17 | B8: 2026-01-09 | C8: 8:17 AM | D8: - | E8: =IF(OR(C8="Absent",D8="Absent",C8="",D8=""),"", (D8-C8)*1440) -> #VALUE! | F8: =IF(OR(C8="",C8="Absent"),"", MAX(0,(C8 - TIME(8,50,0))*1440)) -> 0 | G8: =IF(C8="","", MAX(0,480 - E8)) -> #VALUE! | H8: =IF(OR(TRIM(C8)="Absent", TRIM(C8)="ABSENT"), "Absent", IF(OR(TRIM(C8)="", TRIM(C8)="-", TRIM(D8)="", TRIM(D8)="-"), "Missing", IF( IF(ISNUMBER(C8), C8, IFERROR(TIMEVALUE(C8), 0)) < TIME(8,30,0), "Early", IF( AND( IF(ISNUMBER(C8), C8, IFERROR(TIMEVALUE(C8), 0)) >= TIME(8,30,0), IF(ISNUMBER(C8), C8, IFERROR(TIMEVALUE(C8), 0)) <= TIME(8,50,0), (IF(ISNUMBER(D8), D8, IFERROR(TIMEVALUE(D8), 0)) - IF(ISNUMBER(C8), C8, IFERROR(TIMEVALUE(C8), 0))) >= TIME(8,0,0) ), "On Time", "Late" ) ) ) ) -> Missing | I8: 480
A9: Sheet 17 | B9: 2026-01-12 | C9: 8:17 AM | D9: 8:17 AM | E9: =IF(OR(C9="Absent",D9="Absent",C9="",D9=""),"", (D9-C9)*1440) -> 0 | F9: =IF(OR(C9="",C9="Absent"),"", MAX(0,(C9 - TIME(8,50,0))*1440)) -> 0 | G9: =IF(C9="","", MAX(0,480 - E9)) -> 480 | H9: =IF(OR(TRIM(C9)="Absent", TRIM(C9)="ABSENT"), "Absent", IF(OR(TRIM(C9)="", TRIM(C9)="-", TRIM(D9)="", TRIM(D9)="-"), "Missing", IF( IF(ISNUMBER(C9), C9, IFERROR(TIMEVALUE(C9), 0)) < TIME(8,30,0), "Early", IF( AND( IF(ISNUMBER(C9), C9, IFERROR(TIMEVALUE(C9), 0)) >= TIME(8,30,0), IF(ISNUMBER(C9), C9, IFERROR(TIMEVALUE(C9), 0)) <= TIME(8,50,0), (IF(ISNUMBER(D9), D9, IFERROR(TIMEVALUE(D9), 0)) - IF(ISNUMBER(C9), C9, IFERROR(TIMEVALUE(C9), 0))) >= TIME(8,0,0) ), "On Time", "Late" ) ) ) ) -> Early | I9: 480
A10: Sheet 17 | B10: 2026-01-13 | C10: 8:21 AM | D10: 5:43 PM | E10: =IF(OR(C10="Absent",D10="Absent",C10="",D10=""),"", (D10-C10)*1440) -> 562 | F10: =IF(OR(C10="",C10="Absent"),"", MAX(0,(C10 - TIME(8,50,0))*1440)) -> 0 | G10: =IF(C10="","", MAX(0,480 - E10)) -> 0 | H10: =IF(OR(TRIM(C10)="Absent", TRIM(C10)="ABSENT"), "Absent", IF(OR(TRIM(C10)="", TRIM(C10)="-", TRIM(D10)="", TRIM(D10)="-"), "Missing", IF( IF(ISNUMBER(C10), C10, IFERROR(TIMEVALUE(C10), 0)) < TIME(8,30,0), "Early", IF( AND( IF(ISNUMBER(C10), C10, IFERROR(TIMEVALUE(C10), 0)) >= TIME(8,30,0), IF(ISNUMBER(C10), C10, IFERROR(TIMEVALUE(C10), 0)) <= TIME(8,50,0), (IF(ISNUMBER(D10), D10, IFERROR(TIMEVALUE(D10), 0)) - IF(ISNUMBER(C10), C10, IFERROR(TIMEVALUE(C10), 0))) >= TIME(8,0,0) ), "On Time", "Late" ) ) ) ) -> Early | I10: 480
A11: Sheet 17 | B11: 2026-01-14 | C11: 8:18 AM | D11: 4:53 PM | E11: =IF(OR(C11="Absent",D11="Absent",C11="",D11=""),"", (D11-C11)*1440) -> 515 | F11: =IF(OR(C11="",C11="Absent"),"", MAX(0,(C11 - TIME(8,50,0))*1440)) -> 0 | G11: =IF(C11="","", MAX(0,480 - E11)) -> 0 | H11: =IF(OR(TRIM(C11)="Absent", TRIM(C11)="ABSENT"), "Absent", IF(OR(TRIM(C11)="", TRIM(C11)="-", TRIM(D11)="", TRIM(D11)="-"), "Missing", IF( IF(ISNUMBER(C11), C11, IFERROR(TIMEVALUE(C11), 0)) < TIME(8,30,0), "Early", IF( AND( IF(ISNUMBER(C11), C11, IFERROR(TIMEVALUE(C11), 0)) >= TIME(8,30,0), IF(ISNUMBER(C11), C11, IFERROR(TIMEVALUE(C11), 0)) <= TIME(8,50,0), (IF(ISNUMBER(D11), D11, IFERROR(TIMEVALUE(D11), 0)) - IF(ISNUMBER(C11), C11, IFERROR(TIMEVALUE(C11), 0))) >= TIME(8,0,0) ), "On Time", "Late" ) ) ) ) -> Early | I11: 480
